Workbook
Name FID_1: [1]AGR_Fuels!$A$2
Name GWhtoPJ: 1/277.778
Name hydro_temp: #REF!
Name hydro_temp: #REF!
Name hydro_temp: #REF!
Name input_05: #REF!
Name input_05: #REF!
Name input_05: #REF!
Name last: #REF!
Name last: #REF!
Name last: #REF!
Name latest_year: '[2]MACRO ECONOMIC DATA'!$D$133
Name March_Years: OFFSET('[3]Demand - MY'!$A$11,0,0,COUNTA('[3]Demand - MY'!$A$11:$A$799),1)
Name MWhtoPJ: 0.0000036
Name Net_generation: [4]StationID!$N$3:$Q$153
Name NZ_HES_description: #REF!
Name NZ_HES_description: #REF!
Name NZ_HES_description: #REF!
Name PJfromGWh: 277.778
Name Print_it: [5]!Print_it
Name Print_it: [5]!Print_it
Name Quarters: OFFSET('[3]Primary Energy - Q'!$A$11,0,0,COUNTA('[3]Primary Energy - Q'!$A$11:$A$793),1)
Name Technical_Notes_...: #REF!
Name Technical_Notes_...: #REF!
Name Technical_Notes_...: #REF!
Name temp: #REF!
Name temp: #REF!
Name temp: #REF!
Name TWhtoPJ: 3.6
Name Years: OFFSET('[3]Demand - DY'!$A$11,0,0,COUNTA('[3]Demand - DY'!$A$11:$A$98),1)

Sheet Documentation
A1: Workbook: South Island Other Sector Base Year
A2: PROC_COM_AGR: Agriculture sector technology and enduse commodity definitions
A3: AGR_fuels: Agriculture sector fuel commodity and process definitions
A4: AGR: Agriculture process data
A5: RES_techs_coms: Residential sector technology and enduse commodity definitions
A6: RES_fuel_dem: Residential sector fuel commodity and process definitions
A7: RES: Agriculture process data
A8: COM_techs: Commercial sector technology and enduse commodity definitions
A9: COM_fuels: Commercial sector fuel commodity and process definitions
A10: COM: Commercial sector process data
A11: Emi: Agriculture, residential, and commercial fuel emissions

Sheet EB1
B3: Regional Energy End Use by Fuel Type - Delivered Energy for the Calendar Year 2012 (Terajoules)
B5: Island | C5: Region | D5: Aviation Fuel/Kerosene | E5: Biogas | F5: Black Liquor | G5: Coal | H5: Diesel | I5: Electricity | J5: Fuel Oil | K5: Geothermal | L5: LPG | M5: Natural Gas | N5: Petrol | O5: Solar | P5: Wood | Q5: Grand Total
B6: NI | C6: Auckland Region | D6: 5.0760698 | E6: 0 | F6: 0 | G6: 4.7040854 | H6: 30.353856 | I6: 35.581102 | J6: 1.884448 | K6: 0.058266818 | L6: 2.0048567 | M6: 13.929684 | N6: 38.135748 | O6: 0.12148232 | P6: 9.5274125 | Q6: 141.37701
B7: NI | C7: Bay of Plenty Region | D7: 0.13260687 | E7: 0.024054983 | F7: 9.9478626 | G7: 1.1435761 | H7: 7.0120437 | I7: 9.3897224 | J7: 0.45823449 | K7: 6.5921802 | L7: 0.16889858 | M7: 3.6873565 | N7: 4.9873045 | O7: 0.022977498 | P7: 5.0932435 | Q7: 48.660062
B8: SI | C8: Canterbury Region | D8: 2.6526415 | E8: 0.079513141 | F8: 0 | G8: 4.0231409 | H8: 16.404213 | I8: 18.836871 | J8: 1.036763 | K8: 0.072148549 | L8: 1.8615094 | M8: 0 | N8: 15.441666 | O8: 0.04629407 | P8: 4.8733045 | Q8: 65.328065
B9: NI | C9: Gisborne Region | D9: 0.03361648 | E9: 0 | F9: 0 | G9: 0.24963516 | H9: 1.3037124 | I9: 1.0610033 | J9: 0.089820541 | K9: 0.00013996155 | L9: 0.025363381 | M9: 0.4074518 | N9: 0.75035922 | O9: 0.0037462948 | P9: 0.48418477 | Q9: 4.4090333
B10: NI | C10: Hawke's Bay Region | D10: 0.072715335 | E10: 0 | F10: 0 | G10: 0.77956338 | H10: 4.176743 | I10: 7.1955041 | J10: 0.24770723 | K10: 0.0027630291 | L10: 0.072958221 | M10: 1.9565645 | N10: 2.8167154 | O10: 0.012974162 | P10: 1.8602814 | Q10: 19.19449
B11: NI | C11: Manawatu-Wanganui Region | D11: 0.10916047 | E11: 0 | F11: 0 | G11: 1.7535831 | H11: 5.342402 | I11: 5.0873241 | J11: 0.25885927 | K11: 0 | L11: 0.21271586 | M11: 3.7049107 | N11: 4.6520994 | O11: 0.019109425 | P11: 1.7945471 | Q11: 22.934711
B12: SI | C12: Marlborough Region | D12: 0.062092936 | E12: 0 | F12: 0 | G12: 0.19982417 | H12: 1.976048 | I12: 1.3702089 | J12: 0.20108326 | K12: 0.0012872251 | L12: 0.046250881 | M12: 0 | N12: 0.82225439 | O12: 0.0037259555 | P12: 0.37086394 | Q12: 5.0536397
B13: SI | C13: Nelson Region | D13: 0.35519589 | E13: 0.01443299 | F13: 0 | G13: 0.17115603 | H13: 1.4389495 | I13: 2.2799314 | J13: 0.27337411 | K13: 0 | L13: 0.026859046 | M13: 0 | N13: 0.9061577 | O13: 0.0039852173 | P13: 0.63873611 | Q13: 6.108778
B14: NI | C14: Northland Region | D14: 0.057808582 | E14: 0 | F14: 0 | G14: 1.0708962 | H14: 3.8956292 | I14: 4.7860156 | J14: 0.26735772 | K14: 0.0060928919 | L14: 0.44892452 | M14: 6.2790527 | N14: 3.2058461 | O14: 0.01301793 | P14: 1.7913011 | Q14: 21.821943
B15: SI | C15: Otago Region | D15: 0.34279866 | E15: 0 | F15: 0 | G15: 1.0977015 | H15: 5.7433185 | I15: 4.935668 | J15: 0.33985624 | K15: 0.0051489002 | L15: 1.4892075 | M15: 0 | N15: 6.3539985 | O15: 0.017375949 | P15: 1.5058923 | Q15: 21.830966
B16: SI | C16: Southland Region | D16: 0.06792124 | E16: 0 | F16: 0 | G16: 1.3148228 | H16: 3.675672 | I16: 21.561643 | J16: 0.46876303 | K16: 0 | L16: 0.17159346 | M16: 0 | N16: 2.4737966 | O16: 0.0080103408 | P16: 1.014882 | Q16: 30.757104
B17: NI | C17: Taranaki Region | D17: 0.05206173 | E17: 0 | F17: 0 | G17: 2.1805581 | H17: 4.3243678 | I17: 3.2469849 | J17: 0.16234414 | K17: 0.00010754655 | L17: 0.060911662 | M17: 20.957884 | N17: 2.2789301 | O17: 0.0094065443 | P17: 0.95135167 | Q17: 34.224908
... B21: SI | C21: West Coast Region | D21: 0.022245431 | E21: 0 | F21: 0 | G21: 0.62618635 | H21: 1.9635327 | I21: 1.2607232 | J21: 0.13779825 | K21: 0.012311064 | L21: 0.014712835 | M21: 0 | N21: 0.76520285 | O21: 0.0027589372 | P21: 0.43574307 | Q21: 5.2412146
C22: Grand Total | D22: 11.958228 | E22: 0.33026164 | F22: 16.754295 | G22: 24.58967 | H22: 112.09078 | I22: 140.82561 | J22: 7.2693078 | K22: 9.8455428 | L22: 7.3393583 | M22: 60.585677 | N22: 106.42212 | O22: 0.364 | P22: 38.585738 | Q22: 536.96058
C26: Region | D26: Aviation Fuel/Kerosene | E26: Biogas | F26: Black Liquor | G26: Coal | H26: Diesel | I26: Electricity | J26: Fuel Oil | K26: Geothermal | L26: LPG | M26: Natural Gas | N26: Petrol | O26: Solar | P26: Wood
C27: NI | D27: =SUMIF($B$6:$B$21,$C$27,D6:D21) -> 8.4257065 | E27: =SUMIF($B$6:$B$21,$C$27,E6:E21) -> 0.23631551 | F27: =SUMIF($B$6:$B$21,$C$27,F6:F21) -> 16.754295 | G27: =SUMIF($B$6:$B$21,$C$27,G6:G21) -> 16.780356 | H27: =SUMIF($B$6:$B$21,$C$27,H6:H21) -> 78.813686 | I27: =SUMIF($B$6:$B$21,$C$27,I6:I21) -> 90.014367 | J27: =SUMIF($B$6:$B$21,$C$27,J6:J21) -> 4.5398035 | K27: =SUMIF($B$6:$B$21,$C$27,K6:K21) -> 9.754647 | ... Q27: =SUMIF($B$6:$B$21,$C$27,Q6:Q21) -> 397.51675
C28: SI | D28: =SUMIF($B$6:$B$21,$C$28,D6:D21) -> 3.5325217 | E28: =SUMIF($B$6:$B$21,$C$28,E6:E21) -> 0.093946131 | F28: =SUMIF($B$6:$B$21,$C$28,F6:F21) -> 0 | G28: =SUMIF($B$6:$B$21,$C$28,G6:G21) -> 7.8093141 | H28: =SUMIF($B$6:$B$21,$C$28,H6:H21) -> 33.277091 | I28: =SUMIF($B$6:$B$21,$C$28,I6:I21) -> 50.81124 | J28: =SUMIF($B$6:$B$21,$C$28,J6:J21) -> 2.7295043 | K28: =SUMIF($B$6:$B$21,$C$28,K6:K21) -> 0.090895738 | ... Q28: =SUMIF($B$6:$B$21,$C$28,Q6:Q21) -> 139.44383
C31: Complete New Zealand (TJ) | S31: Share of SI
C32: Sector ANZSIC 2006* | D32: Aviation Fuel/Kerosene | E32: Biogas | F32: Black Liquor | G32: Coal | H32: Diesel | I32: Electricity | J32: Fuel Oil | K32: Geothermal | L32: LPG | M32: Natural Gas | N32: Petrol | O32: Solar | P32: Wood | Q32: Grand Total | S32: Sector ANZSIC 2006* | T32: Aviation Fuel/Kerosene | U32: Biogas | V32: Black Liquor | W32: Coal | X32: Diesel | Y32: Electricity | Z32: Fuel Oil | AA32: Geothermal | AB32: LPG | AC32: Natural Gas | AD32: Petrol | AE32: Solar | AF32: Wood | AG32: Grand Total
C34: Agriculture | D34: 0 | E34: 7.348193 | F34: 0 | G34: 1680.8781 | H34: 22796.672 | I34: 9784.377 | J34: 2323.2179 | K34: 731.7896 | L34: 67.994451 | M34: 1631.7637 | N34: 3844.6756 | O34: 0 | P34: 0 | Q34: 42868.716 | S34: Agriculture
C35: Dairy Cattle Farming | E35: 7.348193 | H35: 5234.9647 | I35: 7091.2888 | N35: 2200.1873 | Q35: 14533.789 | T35: 0.5 | U35: 0.5 | V35: 0.5 | W35: 0.5 | X35: 0.5 | Y35: 0.5 | Z35: 0.5 | AA35: 0.5 | AB35: 0.5 | AC35: 0.5 | AD35: 0.5 | AE35: 0.5 | AF35: 0.5
C36: Fishing, Hunting and Trapping | H36: 2902.9716 | I36: 182.41272 | J36: 2323.2179 | N36: 203.55389 | Q36: 5612.1561 | T36: 0.5 | U36: 0.5 | V36: 0.5 | W36: 0.5 | X36: 0.5 | Y36: 0.5 | Z36: 0.5 | AA36: 0.5 | AB36: 0.5 | AC36: 0.5 | AD36: 0.5 | AE36: 0.5 | AF36: 0.5
C37: Forestry and Logging | G37: 0.64772262 | H37: 2864.0066 | I37: 641.45471 | M37: 0.009674 | N37: 74.529936 | Q37: 3580.6486 | T37: 0.5 | U37: 0.5 | V37: 0.5 | W37: 0.5 | X37: 0.5 | Y37: 0.5 | Z37: 0.5 | AA37: 0.5 | AB37: 0.5 | AC37: 0.5 | AD37: 0.5 | AE37: 0.5 | AF37: 0.5
C38: Indoor Cropping | G38: 1680.2303 | H38: 223.31057 | I38: 33.769723 | K38: 527.18544 | M38: 1631.754 | Q38: 4096.2501 | T38: 0.5 | U38: 0.5 | V38: 0.5 | W38: 0.5 | X38: 0.5 | Y38: 0.5 | Z38: 0.5 | AA38: 0.5 | AB38: 0.5 | AC38: 0.5 | AD38: 0.5 | AE38: 0.5 | AF38: 0.5
C39: Non-Dairy Agriculture | H39: 11571.418 | I39: 1835.4511 | K39: 204.60417 | L39: 67.994451 | N39: 1366.4044 | Q39: 15045.872 | T39: 0.5 | U39: 0.5 | V39: 0.5 | W39: 0.5 | X39: 0.5 | Y39: 0.5 | Z39: 0.5 | AA39: 0.5 | AB39: 0.5 | AC39: 0.5 | AD39: 0.5 | AE39: 0.5 | AF39: 0.5
C40: Commerce | D40: 0 | E40: 280 | F40: 0 | G40: 1128.7058 | H40: 18898.856 | I40: 33673.33 | J40: 4.6744072 | K40: 2251.7423 | L40: 1253.8726 | M40: 8714.2551 | N40: 17028.203 | O40: 0 | P40: 0 | Q40: 83233.639 | S40: Commerce
C41: Accommodation and Food Services | G41: 10.258235 | H41: 324.6865 | I41: 3038.8157 | J41: 0.62127059 | K41: 366.88619 | L41: 230.95187 | M41: 702.91834 | N41: 685.88207 | Q41: 5361.0202 | T41: 0.5 | U41: 0.5 | V41: 0.5 | W41: 0.5 | X41: 0.5 | Y41: 0.5 | Z41: 0.5 | AA41: 0.5 | AB41: 0.5 | AC41: 0.5 | AD41: 0.5 | AE41: 0.5 | AF41: 0.5
C42: Arts, Recreational and Other Services | G42: 36.67147 | H42: 1701.9264 | I42: 2091.2729 | J42: 0.16551393 | K42: 1695.7099 | M42: 343.71567 | N42: 1936.3635 | Q42: 7805.8253 | T42: 0.5 | U42: 0.5 | V42: 0.5 | W42: 0.5 | X42: 0.5 | Y42: 0.5 | Z42: 0.5 | AA42: 0.5 | AB42: 0.5 | AC42: 0.5 | AD42: 0.5 | AE42: 0.5 | AF42: 0.5
C43: Building Cleaning, Pest Control and Other Support Services | H43: 696.33884 | I43: 78.99173 | N43: 737.16655 | Q43: 1512.4971 | T43: 0.5 | U43: 0.5 | V43: 0.5 | W43: 0.5 | X43: 0.5 | Y43: 0.5 | Z43: 0.5 | AA43: 0.5 | AB43: 0.5 | AC43: 0.5 | AD43: 0.5 | AE43: 0.5 | AF43: 0.5
C44: Central Government Administration | G44: 7.6757246 | H44: 64.420543 | I44: 720.67252 | J44: 0.047366043 | M44: 202.11046 | N44: 103.83171 | Q44: 1098.7583 | T44: 0.5 | U44: 0.5 | V44: 0.5 | W44: 0.5 | X44: 0.5 | Y44: 0.5 | Z44: 0.5 | AA44: 0.5 | AB44: 0.5 | AC44: 0.5 | AD44: 0.5 | AE44: 0.5 | AF44: 0.5
C45: Defence | G45: 151.62888 | H45: 1149.7576 | I45: 389.61033 | J45: 2.5587471 | M45: 117.99222 | N45: 1095.7877 | Q45: 2907.3355 | T45: 0.5 | U45: 0.5 | V45: 0.5 | W45: 0.5 | X45: 0.5 | Y45: 0.5 | Z45: 0.5 | AA45: 0.5 | AB45: 0.5 | AC45: 0.5 | AD45: 0.5 | AE45: 0.5 | AF45: 0.5
C46: Education and Training: Pre-School, Primary and Secondary | G46: 17.697647 | H46: 248.19487 | I46: 1670.1537 | J46: 0.11637646 | K46: 27.079541 | M46: 1560.7124 | N46: 165.27072 | Q46: 3689.2252 | T46: 0.5 | U46: 0.5 | V46: 0.5 | W46: 0.5 | X46: 0.5 | Y46: 0.5 | Z46: 0.5 | AA46: 0.5 | AB46: 0.5 | AC46: 0.5 | AD46: 0.5 | AE46: 0.5 | AF46: 0.5
C47: Education and Training: Tertiary Education and Other Education | G47: 10.650218 | H47: 243.69131 | I47: 991.27629 | J47: 0.056303273 | K47: 9.2677689 | M47: 1031.7932 | N47: 390.34371 | Q47: 2677.0788 | T47: 0.5 | U47: 0.5 | V47: 0.5 | W47: 0.5 | X47: 0.5 | Y47: 0.5 | Z47: 0.5 | AA47: 0.5 | AB47: 0.5 | AC47: 0.5 | AD47: 0.5 | AE47: 0.5 | AF47: 0.5
C48: Financing, Insurance, Real Estate and Business Services | G48: 39.233887 | H48: 6683.2682 | I48: 6160.4346 | J48: 0.94776683 | K48: 73.687953 | M48: 718.02145 | N48: 6477.6683 | Q48: 20153.262 | T48: 0.5 | U48: 0.5 | V48: 0.5 | W48: 0.5 | X48: 0.5 | Y48: 0.5 | Z48: 0.5 | AA48: 0.5 | AB48: 0.5 | AC48: 0.5 | AD48: 0.5 | AE48: 0.5 | AF48: 0.5
C49: Health Care and Social Assistance | G49: 142.59675 | H49: 295.38329 | I49: 2305.1493 | J49: 0.070875605 | K49: 79.110938 | M49: 2534.6751 | N49: 555.03984 | Q49: 5912.0261 | T49: 0.5 | U49: 0.5 | V49: 0.5 | W49: 0.5 | X49: 0.5 | Y49: 0.5 | Z49: 0.5 | AA49: 0.5 | AB49: 0.5 | AC49: 0.5 | AD49: 0.5 | AE49: 0.5 | AF49: 0.5
C50: Information Media and Telecommunications | H50: 233.45872 | I50: 2618.0532 | L50: 11.057191 | M50: 3.1739903 | N50: 553.04556 | Q50: 3418.7887 | T50: 0.5 | U50: 0.5 | V50: 0.5 | W50: 0.5 | X50: 0.5 | Y50: 0.5 | Z50: 0.5 | AA50: 0.5 | AB50: 0.5 | AC50: 0.5 | AD50: 0.5 | AE50: 0.5 | AF50: 0.5
C51: Local Government Administration | E51: 280 | G51: 64.731089 | H51: 499.45274 | I51: 1023.2845 | M51: 260.55119 | N51: 479.9172 | Q51: 2607.9367 | T51: 0.5 | U51: 0.5 | V51: 0.5 | W51: 0.5 | X51: 0.5 | Y51: 0.5 | Z51: 0.5 | AA51: 0.5 | AB51: 0.5 | AC51: 0.5 | AD51: 0.5 | AE51: 0.5 | AF51: 0.5
C52: Public Administration and Safety | H52: 2200.2603 | N52: 17.592884 | Q52: 2217.8532 | T52: 0.5 | U52: 0.5 | V52: 0.5 | W52: 0.5 | X52: 0.5 | Y52: 0.5 | Z52: 0.5 | AA52: 0.5 | AB52: 0.5 | AC52: 0.5 | AD52: 0.5 | AE52: 0.5 | AF52: 0.5
...

Sheet PROC_COM_AGR
B4: ~FI_Comm | Q4: ~FI_Process
B5: Csets | C5: Region | D5: CommName | E5: * Fuel | F5: * Enduse | G5: CommDesc | H5: * OLD CommDesc | I5: Unit | J5: LimType | K5: CTSLvl | L5: PeakTS | M5: Ctype | Q5: Sets | R5: Region | S5: TechName | T5: * Sector | U5: * Subsector | V5: * Technology | W5: * Fuel | X5: TechDesc | Y5: * OLD TechDesc | Z5: Tact | AA5: Tcap | AB5: Tslvl | AC5: PrimaryCG | AD5: Vintage
B6: *Commodity Set Membership | C6: Region Name | D6: Commodity Name | H6: Commodity Description | I6: Unit | J6: Sense of the Balance EQN. | K6: Timeslice Level | L6: Peak Monitoring | M6: Electricity Indicator | Q6: *Process Set Membership | R6: Region Name | S6: Technology Name | Y6: Technology Description | Z6: Activity Unit | AA6: Capacity Unit | AB6: TimeSlice level of Process Activity | AC6: Primary Commodity Group | AD6: Vintage Tracking
B7: DEM | D7: ADCF-MoTP-Stat | F7: Milking Machine | G7: =_xlfn.CONCAT(E7, " -:- ", F7) -> -:- Milking Machine | H7: Dairy Cattle Farming Motive Power, Stationary | I7: PJ | Q7: *
B8: DEM | D8: ADCF-IRG | F8: Irrigation | G8: =_xlfn.CONCAT(E8, " -:- ", F8) -> -:- Irrigation | H8: Dairy Cattle Farming Irrigation | I8: PJ | Q8: DMD | S8: ADCF-MoTP-Stat-VacP_ELC00 | T8: Agriculture | U8: Dairy Cattle Farming | V8: Vacuum Pump | W8: Electricity | X8: =_xlfn.CONCAT( T8, " -:- ", U8, " -:- ", V8, " -:- ", W8) -> Agriculture -:- Dairy Cattle Farming -:- Vacuum Pump -:- Electricity | Y8: Dairy Cattle Farming-Vacuum Pump | Z8: PJ | AA8: GW
B9: DEM | D9: ADCF-WH | F9: Water Heating | G9: =_xlfn.CONCAT(E9, " -:- ", F9) -> -:- Water Heating | H9: Dairy Cattle Farming Low Temperature Heat (<100 C), Water Heating | I9: PJ | Q9: DMD | S9: ADCF-MoTP-Stat-VPVSD_ELC00 | T9: Agriculture | U9: Dairy Cattle Farming | V9: Vacuum Pump with VSD | W9: Electricity | X9: =_xlfn.CONCAT( T9, " -:- ", U9, " -:- ", V9, " -:- ", W9) -> Agriculture -:- Dairy Cattle Farming -:- Vacuum Pump with VSD -:- Electricity | Y9: Dairy Cattle Farming-Vacuum pump with VSD | Z9: PJ | AA9: GW
B10: DEM | D10: ADCF-MoTP-Mob-Trac | F10: Tractor Services | G10: =_xlfn.CONCAT(E10, " -:- ", F10) -> -:- Tractor Services | H10: Dairy Cattle Farming Motive Power, Mobile | I10: PJ | Q10: DMD | S10: ADCF-IRG-Irg_ELC00 | T10: Agriculture | U10: Dairy Cattle Farming | V10: Irrigator | W10: Electricity | X10: =_xlfn.CONCAT( T10, " -:- ", U10, " -:- ", V10, " -:- ", W10) -> Agriculture -:- Dairy Cattle Farming -:- Irrigator -:- Electricity | Y10: Dairy Cattle Farming-Irrigation | Z10: PJ | AA10: GW
B11: DEM | D11: ADCF-MoTP-Mob-MTr | F11: Truck Services | G11: =_xlfn.CONCAT(E11, " -:- ", F11) -> -:- Truck Services | H11: Dairy Cattle Farming Motive Power, Mobile | I11: PJ | Q11: DMD | S11: ADCF-IRG-IrgVSD_ELC00 | T11: Agriculture | U11: Dairy Cattle Farming | V11: Irrigator with VSD | W11: Electricity | X11: =_xlfn.CONCAT( T11, " -:- ", U11, " -:- ", V11, " -:- ", W11) -> Agriculture -:- Dairy Cattle Farming -:- Irrigator with VSD -:- Electricity | Y11: Dairy Cattle Farming-Irrigation with VSD | Z11: PJ | AA11: GW
B12: DEM | D12: ADCF-MoTP-Mob-Uti | F12: Farm Vehicle | G12: =_xlfn.CONCAT(E12, " -:- ", F12) -> -:- Farm Vehicle | H12: Dairy Cattle Farming Motive Power, Mobile | I12: PJ | Q12: DMD | S12: ADCF-WH-Cylinder_ELC00 | T12: Agriculture | U12: Dairy Cattle Farming | V12: Hot Water Cylinder | W12: Electricity | X12: =_xlfn.CONCAT( T12, " -:- ", U12, " -:- ", V12, " -:- ", W12) -> Agriculture -:- Dairy Cattle Farming -:- Hot Water Cylinder -:- Electricity | Y12: Dairy Cattle Farming-Hot Water Cylinder | Z12: PJ | AA12: GW
B13: DEM | D13: ADCF-MoTP-Mob-Bike | F13: Off-road Motorbike Use | G13: =_xlfn.CONCAT(E13, " -:- ", F13) -> -:- Off-road Motorbike Use | H13: Dairy Cattle Farming Motive Power, Mobile | I13: PJ | Q13: DMD | S13: ADCF-WH-Hreco_ELC00 | T13: Agriculture | U13: Dairy Cattle Farming | V13: Heat Recovery System (Heating) | W13: Electricity | X13: =_xlfn.CONCAT( T13, " -:- ", U13, " -:- ", V13, " -:- ", W13) -> Agriculture -:- Dairy Cattle Farming -:- Heat Recovery System (Heating) -:- Electricity | Y13: Dairy Cattle Farming-Heat Recovery & Heat Pump | Z13: PJ | AA13: GW
B14: DEM | D14: ADCF-PUMP | F14: Pumping | G14: =_xlfn.CONCAT(E14, " -:- ", F14) -> -:- Pumping | H14: Dairy Cattle Farming Pumping | I14: PJ | Q14: DMD | S14: ADCF-MoTP-Mob-Trac-_DSL00 | T14: Agriculture | U14: Dairy Cattle Farming | V14: Tractor (Agricultural) | W14: Diesel | X14: =_xlfn.CONCAT( T14, " -:- ", U14, " -:- ", V14, " -:- ", W14) -> Agriculture -:- Dairy Cattle Farming -:- Tractor (Agricultural) -:- Diesel | Y14: Dairy Cattle Farming-Tractor | Z14: PJ | AA14: GW
B15: DEM | D15: ADCF-RFGR | F15: Refrigeration | G15: =_xlfn.CONCAT(E15, " -:- ", F15) -> -:- Refrigeration | H15: Dairy Cattle Farming Refrigeration | I15: PJ | Q15: DMD | S15: ADCF-MoTP-Mob-MTr-_DSL00 | T15: Agriculture | U15: Dairy Cattle Farming | V15: Truck (Agricultural) | W15: Diesel | X15: =_xlfn.CONCAT( T15, " -:- ", U15, " -:- ", V15, " -:- ", W15) -> Agriculture -:- Dairy Cattle Farming -:- Truck (Agricultural) -:- Diesel | Y15: Dairy Cattle Farming-Medium Truck | Z15: PJ | AA15: GW
B16: DEM | D16: ADCF-LIG | F16: Lighting | G16: =_xlfn.CONCAT(E16, " -:- ", F16) -> -:- Lighting | H16: Dairy Cattle Farming Lighting | I16: PJ | Q16: DMD | S16: ADCF-MoTP-Mob-Uti-_DSL00 | T16: Agriculture | U16: Dairy Cattle Farming | V16: Utility Vehicle (Agricultural) | W16: Diesel | X16: =_xlfn.CONCAT( T16, " -:- ", U16, " -:- ", V16, " -:- ", W16) -> Agriculture -:- Dairy Cattle Farming -:- Utility Vehicle (Agricultural) -:- Diesel | Y16: Dairy Cattle Farming-Utility | Z16: PJ | AA16: GW
B17: DEM | D17: ALIVE-IRG | F17: Irrigation | G17: =_xlfn.CONCAT(E17, " -:- ", F17) -> -:- Irrigation | H17: Livestock Farming Irrigation | I17: PJ | Q17: DMD | S17: ADCF-MoTP-Mob-Bike-_PET00 | T17: Agriculture | U17: Dairy Cattle Farming | V17: Farm Bike | W17: Petrol | X17: =_xlfn.CONCAT( T17, " -:- ", U17, " -:- ", V17, " -:- ", W17) -> Agriculture -:- Dairy Cattle Farming -:- Farm Bike -:- Petrol | Y17: Dairy Cattle Farming-Motorbike/side by side | Z17: PJ | AA17: GW
B18: DEM | D18: ALIVE-MoTP-Mob-Trac | F18: Tractor Services | G18: =_xlfn.CONCAT(E18, " -:- ", F18) -> -:- Tractor Services | H18: Livestock Farming Motive Power, Mobile | I18: PJ | Q18: DMD | S18: ADCF-PUMP-Pump_ELC00 | T18: Agriculture | U18: Dairy Cattle Farming | V18: Transfer Pump | W18: Electricity | X18: =_xlfn.CONCAT( T18, " -:- ", U18, " -:- ", V18, " -:- ", W18) -> Agriculture -:- Dairy Cattle Farming -:- Transfer Pump -:- Electricity | Y18: Dairy Cattle Farming-Transfer Pumps etc | Z18: PJ | AA18: GW
B19: DEM | D19: ALIVE-MoTP-Mob-MTr | F19: Truck Services | G19: =_xlfn.CONCAT(E19, " -:- ", F19) -> -:- Truck Services | H19: Livestock Farming Motive Power, Mobile | I19: PJ | Q19: DMD | S19: ADCF-RFGR-RF_ELC00 | T19: Agriculture | U19: Dairy Cattle Farming | V19: Refrigerator | W19: Electricity | X19: =_xlfn.CONCAT( T19, " -:- ", U19, " -:- ", V19, " -:- ", W19) -> Agriculture -:- Dairy Cattle Farming -:- Refrigerator -:- Electricity | Y19: Dairy Cattle Farming-Refrigeration | Z19: PJ | AA19: GW
... B41: DEM | D41: AOTH-PET | F41: Other | G41: =_xlfn.CONCAT(E41, " -:- ", F41) -> -:- Other | H41: Other Other - Petrol | I41: PJ | Q41: DMD | S41: AFORE-MoTP-Mob-GB-_DSL00 | T41: Agriculture | U41: Forestry | V41: Skidder (Forestry) | W41: Diesel | X41: =_xlfn.CONCAT( T41, " -:- ", U41, " -:- ", V41, " -:- ", W41) -> Agriculture -:- Forestry -:- Skidder (Forestry) -:- Diesel | Y41: Forestry and Logging-Ground Based | Z41: PJ | AA41: GW
Q42: DMD | S42: AFORE-MoTP-Mob-CY-_DSL00 | T42: Agriculture | U42: Forestry | V42: Cable Yarder (Forestry) | W42: Diesel | X42: =_xlfn.CONCAT( T42, " -:- ", U42, " -:- ", V42, " -:- ", W42) -> Agriculture -:- Forestry -:- Cable Yarder (Forestry) -:- Diesel | Y42: Forestry and Logging-Cable Yarding | Z42: PJ | AA42: GW
Q43: DMD | S43: AFORE-LIG-LT_ELC00 | T43: Agriculture | U43: Forestry | V43: Lights (General) | W43: Electricity | X43: =_xlfn.CONCAT( T43, " -:- ", U43, " -:- ", V43, " -:- ", W43) -> Agriculture -:- Forestry -:- Lights (General) -:- Electricity | Y43: Forestry and Logging-Light | Z43: PJ | AA43: GW
Q44: DMD | S44: AFISH-BOAT-Boat_DSL00 | T44: Agriculture | U44: Fishing | V44: Fishing Boat (Non-Hybrid) | W44: Diesel | X44: =_xlfn.CONCAT( T44, " -:- ", U44, " -:- ", V44, " -:- ", W44) -> Agriculture -:- Fishing -:- Fishing Boat (Non-Hybrid) -:- Diesel | Y44: Fishing, Hunting and Trapping-Boat | Z44: PJ | AA44: GW
Q45: DMD | S45: AFISH-BOAT-Boat_FOL00 | T45: Agriculture | U45: Fishing | V45: Fishing Boat (Non-Hybrid) | W45: Fuel Oil | X45: =_xlfn.CONCAT( T45, " -:- ", U45, " -:- ", V45, " -:- ", W45) -> Agriculture -:- Fishing -:- Fishing Boat (Non-Hybrid) -:- Fuel Oil | Y45: Fishing, Hunting and Trapping-Boat | Z45: PJ | AA45: GW
Q46: DMD | S46: AFISH-RFGR-RF_ELC00 | T46: Agriculture | U46: Fishing | V46: Refrigerator | W46: Electricity | X46: =_xlfn.CONCAT( T46, " -:- ", U46, " -:- ", V46, " -:- ", W46) -> Agriculture -:- Fishing -:- Refrigerator -:- Electricity | Y46: Fishing, Hunting and Trapping-Refrigeration | Z46: PJ | AA46: GW
Q47: DMD | S47: AFISH-LIG-LT_ELC00 | T47: Agriculture | U47: Fishing | V47: Lights (General) | W47: Electricity | X47: =_xlfn.CONCAT( T47, " -:- ", U47, " -:- ", V47, " -:- ", W47) -> Agriculture -:- Fishing -:- Lights (General) -:- Electricity | Y47: Fishing, Hunting and Trapping-Light | Z47: PJ | AA47: GW
Q48: DMD | S48: AOTH-ELC-_ELC00 | T48: Agriculture | U48: Other (Agriculture) | V48: Other | W48: Electricity | X48: =_xlfn.CONCAT( T48, " -:- ", U48, " -:- ", V48, " -:- ", W48) -> Agriculture -:- Other (Agriculture) -:- Other -:- Electricity | Y48: Other-Electricity | Z48: PJ | AA48: Pja
Q49: DMD | S49: AOTH-FOL-_FOL00 | T49: Agriculture | U49: Other (Agriculture) | V49: Other | W49: Fuel Oil | X49: =_xlfn.CONCAT( T49, " -:- ", U49, " -:- ", V49, " -:- ", W49) -> Agriculture -:- Other (Agriculture) -:- Other -:- Fuel Oil | Y49: Other-Fuel Oil | Z49: PJ | AA49: Pja
Q50: DMD | S50: AOTH-LPG-_LPG00 | T50: Agriculture | U50: Other (Agriculture) | V50: Other | W50: LPG | X50: =_xlfn.CONCAT( T50, " -:- ", U50, " -:- ", V50, " -:- ", W50) -> Agriculture -:- Other (Agriculture) -:- Other -:- LPG | Y50: Other-LPG | Z50: PJ | AA50: Pja
Q51: DMD | S51: AOTH-PET-_PET00 | T51: Agriculture | U51: Other (Agriculture) | V51: Other | W51: Petrol | X51: =_xlfn.CONCAT( T51, " -:- ", U51, " -:- ", V51, " -:- ", W51) -> Agriculture -:- Other (Agriculture) -:- Other -:- Petrol | Y51: Other-Petrol | Z51: PJ | AA51: Pja

Sheet AGR_fuels
B1: Sector Name | C1: Commodity | D1: Description | E1: Deafult unit | F1: Currency | G1: Existing
B2: AGR | C2: Agriculture | D2: Sector Fuel | E2: PJ | F2: Million NZD (2015) | G2: E
B4: ~FI_Comm | Q4: ~FI_Process
B5: Csets | C5: Region | D5: CommName | E5: * Fuel | F5: * Enduse | G5: CommDesc | H5: * OLD CommDesc | I5: Unit | J5: LimType | K5: CTSLvl | L5: PeakTS | M5: Ctype | Q5: Sets | R5: Region | S5: TechName | T5: * Sector | U5: * Subsector | V5: * Technology | W5: * Fuel | X5: TechDesc | Y5: * OLD TechDesc | Z5: Tact | AA5: Tcap | AB5: Tslvl | AC5: PrimaryCG | AD5: Vintage
B6: *Commodity Set Membership | C6: Region Name | D6: Commodity Name | H6: Commodity Description | I6: Unit | J6: Sense of the Balance EQN. | K6: Timeslice Level | L6: Peak Monitoring | M6: Electricity Indicator | Q6: *Process Set Membership | R6: Region Name | S6: Technology Name | Y6: Technology Description | Z6: Activity Unit | AA6: Capacity Unit | AB6: TimeSlice level of Process Activity | AC6: Primary Commodity Group | AD6: Vintage Tracking
B7: NRG | D7: AGRCOA | E7: Coal | G7: =_xlfn.CONCAT(E7, " -:- ", F7 ) -> Coal -:- | H7: Agriculture Coal | I7: PJ | J7: FX | K7: ANNUAL | Q7: *
B8: NRG | D8: AGRDSL | E8: Diesel | G8: =_xlfn.CONCAT(E8, " -:- ", F8 ) -> Diesel -:- | H8: Agriculture diesel oil | I8: PJ | J8: FX | K8: ANNUAL | Q8: PRE | S8: FTE_AGRCOA | T8: Agriculture | W8: Coal | X8: =_xlfn.CONCAT( T8, " -:- ", U8, " -:- ", V8, " -:- ", W8) -> Agriculture -:- -:- -:- Coal | Y8: Sector Fuel Technology Existing Coal | Z8: PJ | AA8: PJa | AB8: ANNUAL
B9: NRG | D9: AGRPET | E9: Petrol | G9: =_xlfn.CONCAT(E9, " -:- ", F9 ) -> Petrol -:- | H9: Agriculture petroleum | I9: PJ | J9: FX | K9: ANNUAL | Q9: PRE | S9: =+B23 -> FTE_AGRDSL | T9: Agriculture | W9: Diesel | X9: =_xlfn.CONCAT( T9, " -:- ", U9, " -:- ", V9, " -:- ", W9) -> Agriculture -:- -:- -:- Diesel | Y9: =+"Sector Fuel Supply - "&H8 -> Sector Fuel Supply - Agriculture diesel oil | Z9: PJ | AA9: PJa | AB9: ANNUAL
B10: NRG | D10: AGRFOL | E10: Fuel Oil | G10: =_xlfn.CONCAT(E10, " -:- ", F10 ) -> Fuel Oil -:- | H10: Agriculture fuel oil | I10: PJ | J10: FX | K10: ANNUAL | Q10: PRE | S10: =+B25 -> FTE_AGRPET | T10: Agriculture | W10: Petrol | X10: =_xlfn.CONCAT( T10, " -:- ", U10, " -:- ", V10, " -:- ", W10) -> Agriculture -:- -:- -:- Petrol | Y10: =+"Sector Fuel Supply - "&H9 -> Sector Fuel Supply - Agriculture petroleum | Z10: PJ | AA10: PJa | AB10: ANNUAL
B11: NRG | D11: AGRLPG | E11: LPG | G11: =_xlfn.CONCAT(E11, " -:- ", F11 ) -> LPG -:- | H11: Agriculture LPG | I11: PJ | J11: FX | K11: ANNUAL | Q11: PRE | S11: =+B26 -> FTE_AGRFOL | T11: Agriculture | W11: Fuel Oil | X11: =_xlfn.CONCAT( T11, " -:- ", U11, " -:- ", V11, " -:- ", W11) -> Agriculture -:- -:- -:- Fuel Oil | Y11: =+"Sector Fuel Supply - "&H10 -> Sector Fuel Supply - Agriculture fuel oil | Z11: PJ | AA11: PJa | AB11: ANNUAL
B12: NRG | D12: AGRWOD | E12: Wood | G12: =_xlfn.CONCAT(E12, " -:- ", F12 ) -> Wood -:- | H12: Agriculture wood | I12: PJ | J12: FX | K12: ANNUAL | Q12: PRE | S12: =+B27 -> FTE_AGRLPG | T12: Agriculture | W12: LPG | X12: =_xlfn.CONCAT( T12, " -:- ", U12, " -:- ", V12, " -:- ", W12) -> Agriculture -:- -:- -:- LPG | Y12: =+"Sector Fuel Supply - "&H11 -> Sector Fuel Supply - Agriculture LPG | Z12: PJ | AA12: PJa | AB12: ANNUAL
B13: NRG | D13: AGRPLT | E13: Pellet | G13: =_xlfn.CONCAT(E13, " -:- ", F13 ) -> Pellet -:- | H13: Agriculture pellet | I13: PJ | J13: FX | K13: ANNUAL | Q13: PRE | S13: =+B28 -> FTE_AGRWOD | T13: Agriculture | W13: Wood | X13: =_xlfn.CONCAT( T13, " -:- ", U13, " -:- ", V13, " -:- ", W13) -> Agriculture -:- -:- -:- Wood | Y13: =+"Sector Fuel Supply - "&H12 -> Sector Fuel Supply - Agriculture wood | Z13: PJ | AA13: PJa | AB13: ANNUAL
B14: ENV | D14: AGRCO2 | G14: =_xlfn.CONCAT(E14, " -:- ", F14 ) -> -:- | H14: Agriculture emissions | I14: kt | Q14: PRE | S14: =+B29 -> FTE_AGRPLT | T14: Agriculture | W14: Pellet | X14: =_xlfn.CONCAT( T14, " -:- ", U14, " -:- ", V14, " -:- ", W14) -> Agriculture -:- -:- -:- Pellet | Y14: =+"Sector Fuel Supply - "&H13 -> Sector Fuel Supply - Agriculture pellet | Z14: PJ | AA14: PJa | AB14: ANNUAL
D17: ~FI_T
B18: TechName | C18: Comm-IN | D18: Comm-OUT | E18: Share-I~UP | F18: Share-I~UP~2025 | G18: *Share-I~UP~2060 | H18: Share-I~UP~0 | I18: EFF | J18: LIFE | K18: EFF~2021 | L18: EFF~2025 | M18: EFF~2040 | N18: EFF~2060 | O18: EFF~0 | P18: INVCOST | Q18: FIXOM | R18: VAROM | S18: FLO_DELIV
B19: *Technology Name | C19: Input Commodity | D19: Output Commodity | E19: Input Share | F19: Input Share | G19: Input Share | H19: Input Share | I19: Efficiency | J19: Lifetime | P19: Capital costs | Q19: Fixed O&M | R19: Variable O&M
B20: *Units | J20: Years | P20: MNZD/Pja | Q20: MNZD/Pja | R20: MNZD/PJ
B21: FTE_AGRCOA | C21: COA | D21: AGRCOA | E21: 1 | F21: 1 | H21: 5 | I21: 1 | J21: 100
C22: COL | E22: 0.05 | F22: =+E22 -> 0.05
B23: =+"FTE_AGR"&C23 -> FTE_AGRDSL | C23: =+RIGHT(D23,3) -> DSL | D23: =+D8 -> AGRDSL | E23: 1 | F23: 1 | I23: 1 | J23: 100 | R23: 0.92
C24: DID | E24: 1 | F24: 1 | S24: 2.4
B25: =+"FTE_AGR"&C25 -> FTE_AGRPET | C25: =+RIGHT(D25,3) -> PET | D25: =+D9 -> AGRPET | I25: 1 | J25: 100 | R25: 0.92
B26: =+"FTE_AGR"&C26 -> FTE_AGRFOL | C26: =+RIGHT(D26,3) -> FOL | D26: =+D10 -> AGRFOL | I26: 1 | J26: 100
B27: =+"FTE_AGR"&C27 -> FTE_AGRLPG | C27: =+RIGHT(D27,3) -> LPG | D27: =+D11 -> AGRLPG | I27: 1 | J27: 100
B28: =+"FTE_AGR"&C28 -> FTE_AGRWOD | C28: WOD | D28: =+D12 -> AGRWOD | I28: 1 | J28: 100
B29: =+"FTE_AGR"&C29 -> FTE_AGRPLT | C29: PLT | D29: =+D13 -> AGRPLT | I29: 1 | J29: 100

Sheet AGR
E2: ~FI_T
C3: TechName | D3: Comm-IN | E3: Comm-OUT | F3: PRC_RESID | G3: *Delivered energy 2018 | H3: EFF | I3: LIFE | J3: INVCOST | K3: FIXOM | L3: CAP2ACT | M3: ACT_BND | N3: AFA
C4: *Technology Name | D4: Input Commodity | E4: Output Commodity | F4: Existing Installed Capacity | G4: *Energy from EEUD | H4: Efficiency | I4: Lifetime | J4: CAPEX | K4: FIXED O&M | L4: Capacity to activity factor | M4: Actual end-use in 2018 | N4: Annual utilisation factor
C5: *Units | F5: GW | G5: *PJ | H5: % | I5: Years | J5: NZD/kW | K5: NZD/kW/yr | M5: End-use PJ | N5: %
C6: ADCF-MoTP-Stat-VacP_ELC00 | D6: AGRELC | E6: ADCF-MoTP-Stat | F6: 0.022523372 | G6: 0.19110074 | H6: 0.84 | I6: 25 | J6: 410.6135 | K6: 14.445557 | L6: 31.536 | M6: 0.16052462 | N6: 0.22599646
C7: ADCF-MoTP-Stat-VPVSD_ELC00 | D7: AGRELC | E7: ADCF-MoTP-Stat | F7: 0.035345118 | G7: 0.26390102 | H7: 0.95454545 | I7: 25 | J7: 643.4135 | K7: 14.445557 | L7: 31.536 | M7: 0.25190552 | N7: 0.22599646
C8: ADCF-IRG-Irg_ELC00 | D8: AGRELC | E8: ADCF-IRG | F8: 0.1305891 | G8: 0.95782043 | H8: 0.7 | I8: 20 | J8: 6000 | K8: 917.19323 | L8: 31.536 | M8: 0.6704743 | N8: 0.16280532
C9: ADCF-IRG-IrgVSD_ELC00 | D9: AGRELC | E9: ADCF-IRG | F9: 0.051691521 | G9: 0.31927348 | H9: 0.83125 | I9: 20 | J9: 6257.143 | K9: 917.19323 | L9: 31.536 | M9: 0.26539608 | N9: 0.16280532
C10: ADCF-WH-Cylinder_ELC00 | D10: AGRELC | E10: ADCF-WH | F10: 0.032996602 | G10: 0.2828747 | H10: 0.83134897 | I10: 20 | J10: 518.5169 | K10: 18.241644 | L10: 31.536 | M10: 0.23516759 | N10: 0.22599646
C11: ADCF-WH-Hreco_ELC00 | D11: AGRELC | E11: ADCF-WH | F11: 0.085142384 | G11: 0.17337481 | H11: 3.5 | I11: 20 | J11: 1525.072 | K11: 53.652675 | L11: 31.536 | M11: 0.60681185 | N11: 0.22599646
C12: ADCF-MoTP-Mob-Trac-_DSL00 | D12: AGRDSL | E12: ADCF-MoTP-Mob-Trac | F12: 1.703984 | G12: 1.4005348 | H12: 0.11111111 | I12: 15 | J12: 965.2941 | K12: 38.611763 | L12: 1 | M12: 0.15561497 | N12: 0.091324201
C13: ADCF-MoTP-Mob-MTr-_DSL00 | D13: AGRDSL | E13: ADCF-MoTP-Mob-MTr | F13: 2.1936931 | G13: 0.40015279 | H13: 0.12516299 | I13: 22 | J13: 264.043 | K13: 70.396142 | L13: 1 | M13: 0.050084318 | N13: 0.02283105
C14: ADCF-MoTP-Mob-Uti-_DSL00 | D14: AGRDSL | E14: ADCF-MoTP-Mob-Uti | F14: 0.5038924 | G14: 0.20007639 | H14: 0.23 | I14: 22 | J14: 1851.867 | K14: 11.879812 | L14: 1 | M14: 0.046017571 | N14: 0.091324201
C15: ADCF-MoTP-Mob-Bike-_PET00 | D15: AGRPET | E15: ADCF-MoTP-Mob-Bike | F15: 0.11484717 | G15: 0.28711793 | H15: 0.1 | I15: 10 | J15: 363.4258 | K15: 34.750457 | L15: 1 | M15: 0.028711793 | N15: 0.25
C16: ADCF-PUMP-Pump_ELC00 | D16: AGRELC | E16: ADCF-PUMP | F16: 0.050877907 | G16: 0.51801155 | H16: 0.7 | I16: 25 | J16: 886.9063 | K16: 31.201736 | L16: 31.536 | M16: 0.36260808 | N16: 0.22599646
C17: ADCF-RFGR-RF_ELC00 | D17: AGRELC | E17: ADCF-RFGR | F17: 0.087844423 | G17: 0.2121123 | H17: 2.9515937 | I17: 15 | J17: 1637.346 | K17: 57.602515 | L17: 31.536 | M17: 0.62606934 | N17: 0.22599646
... C45: AFISH-LIG-LT_ELC00 | D45: AGRELC | E45: AFISH-LIG | F45: 0.0002762151 | G45: 0.0082024655 | H45: 0.24 | I45: 3.4246575 | J45: 365.1304 | K45: 0 | L45: 31.536 | M45: 0.0019685917 | N45: 0.22599646
C46: AOTH-ELC-_ELC00 | D46: AGRELC | E46: AOTH-ELC | G46: 0.011645478 | H46: 1 | L46: 1 | M46: =+G46 -> 0.011645478 | N46: 1
C47: AOTH-FOL-_FOL00 | D47: AGRFOL | E47: AOTH-FOL | G47: 0.015942326 | H47: 1 | L47: 1 | M47: =+G47 -> 0.015942326 | N47: 1
C48: AOTH-LPG-_LPG00 | D48: AGRLPG | E48: AOTH-LPG | G48: 0.055427963 | H48: 1 | L48: 1 | M48: =+G48 -> 0.055427963 | N48: 1
C49: AOTH-PET-_PET00 | D49: AGRPET | E49: AOTH-PET | G49: 0.0069424525 | H49: 1 | L49: 1 | M49: =+G49 -> 0.0069424525 | N49: 1
C55: ~FI_T
C56: CommName | D56: Demand~2018
C57: ADCF-MoTP-Stat | D57: =+ROUNDDOWN(SUMIF($E$6:$E$49,C57,$M$6:$M$49),3) -> 0.412
C58: ADCF-IRG | D58: =+ROUNDDOWN(SUMIF($E$6:$E$49,C58,$M$6:$M$49),3) -> 0.935
C59: ADCF-WH | D59: =+ROUNDDOWN(SUMIF($E$6:$E$49,C59,$M$6:$M$49),3) -> 0.841
C60: ADCF-MoTP-Mob-Trac | D60: =+ROUNDDOWN(SUMIF($E$6:$E$49,C60,$M$6:$M$49),3) -> 0.155
C61: ADCF-MoTP-Mob-MTr | D61: =+ROUNDDOWN(SUMIF($E$6:$E$49,C61,$M$6:$M$49),3) -> 0.05
C62: ADCF-MoTP-Mob-Uti | D62: =+ROUNDDOWN(SUMIF($E$6:$E$49,C62,$M$6:$M$49),3) -> 0.046
C63: ADCF-MoTP-Mob-Bike | D63: =+ROUNDDOWN(SUMIF($E$6:$E$49,C63,$M$6:$M$49),3) -> 0.028
C64: ADCF-PUMP | D64: =+ROUNDDOWN(SUMIF($E$6:$E$49,C64,$M$6:$M$49),3) -> 0.362
C65: ADCF-RFGR | D65: =+ROUNDDOWN(SUMIF($E$6:$E$49,C65,$M$6:$M$49),3) -> 1.368
C66: ADCF-LIG | D66: =+ROUNDDOWN(SUMIF($E$6:$E$49,C66,$M$6:$M$49),3) -> 0.004
C67: ALIVE-IRG | D67: =+ROUNDDOWN(SUMIF($E$6:$E$49,C67,$M$6:$M$49),3) -> 0.48
C68: ALIVE-MoTP-Mob-Trac | D68: =+ROUNDDOWN(SUMIF($E$6:$E$49,C68,$M$6:$M$49),3) -> 0.115
... C91: AOTH-PET | D91: =+ROUNDDOWN(SUMIF($E$6:$E$49,C91,$M$6:$M$49),3) -> 0.006

Sheet RES_techs_coms
B1: Residential sector commodity and process descriptions
B6: ~FI_Comm | P6: ~FI_Process
B7: Csets | C7: CommName | D7: * Fuel | E7: * Enduse | F7: CommDesc | G7: * OLD CommDesc | H7: Unit | I7: LimType | J7: CTSLvl | K7: PeakTS | L7: Ctype | P7: Sets | Q7: TechName | R7: * Sector | S7: * Subsector | T7: * Technology | U7: * Fuel | V7: TechDesc | W7: * OLD TechDesc | X7: Tact | Y7: Tcap | Z7: Tslvl | AA7: PrimaryCG | AB7: Vintage
B8: NRG | C8: RESCOA | D8: Coal | F8: =_xlfn.CONCAT(D8, " -:- ", E8) -> Coal -:- | G8: Residential Coal | H8: PJ | I8: FX | P8: PRE | Q8: ="FTE_"&C8&"_00" -> FTE_RESCOA_00 | R8: Residential | U8: Coal | V8: =_xlfn.CONCAT( R8, " -:- ", S8, " -:- ", T8, " -:- ", U8) -> Residential -:- -:- -:- Coal | W8: ="Distribution network for "&G8 -> Distribution network for Residential Coal | X8: PJ | Y8: PJ_a
B9: NRG | C9: RESNGA | D9: Natural Gas | F9: =_xlfn.CONCAT(D9, " -:- ", E9) -> Natural Gas -:- | G9: Residential Natural gas | H9: PJ | I9: FX | P9: PRE | Q9: ="FTE_"&C9&"_00" -> FTE_RESNGA_00 | R9: Residential | U9: Natural Gas | V9: =_xlfn.CONCAT( R9, " -:- ", S9, " -:- ", T9, " -:- ", U9) -> Residential -:- -:- -:- Natural Gas | W9: ="Distribution network for "&G9 -> Distribution network for Residential Natural gas | X9: PJ | Y9: PJ_a
B10: NRG | C10: RESLPG | D10: LPG | F10: =_xlfn.CONCAT(D10, " -:- ", E10) -> LPG -:- | G10: Residential LPG | H10: PJ | I10: FX | P10: PRE | Q10: ="FTE_"&C10&"_00" -> FTE_RESLPG_00 | R10: Residential | U10: LPG | V10: =_xlfn.CONCAT( R10, " -:- ", S10, " -:- ", T10, " -:- ", U10) -> Residential -:- -:- -:- LPG | W10: ="Distribution network for "&G10 -> Distribution network for Residential LPG | X10: PJ | Y10: PJ_a
B11: NRG | C11: RESDSL | D11: Diesel | F11: =_xlfn.CONCAT(D11, " -:- ", E11) -> Diesel -:- | G11: Residential Diesel | H11: PJ | I11: FX | P11: PRE | Q11: ="FTE_"&C11&"_00" -> FTE_RESDSL_00 | R11: Residential | U11: Diesel | V11: =_xlfn.CONCAT( R11, " -:- ", S11, " -:- ", T11, " -:- ", U11) -> Residential -:- -:- -:- Diesel | W11: ="Distribution network for "&G11 -> Distribution network for Residential Diesel | X11: PJ | Y11: PJ_a
B12: NRG | C12: RESWOD | D12: Wood | F12: =_xlfn.CONCAT(D12, " -:- ", E12) -> Wood -:- | G12: Residential Firewood | H12: PJ | I12: FX | P12: PRE | Q12: ="FTE_"&C12&"_00" -> FTE_RESWOD_00 | R12: Residential | U12: Wood | V12: =_xlfn.CONCAT( R12, " -:- ", S12, " -:- ", T12, " -:- ", U12) -> Residential -:- -:- -:- Wood | W12: ="Distribution network for "&G12 -> Distribution network for Residential Firewood | X12: PJ | Y12: PJ_a
B13: NRG | C13: RESGEO | D13: Geothermal | F13: =_xlfn.CONCAT(D13, " -:- ", E13) -> Geothermal -:- | G13: Residential Geothermal | H13: PJ | I13: FX | P13: PRE | Q13: ="FTE_"&C13&"_00" -> FTE_RESGEO_00 | R13: Residential | U13: Geothermal | V13: =_xlfn.CONCAT( R13, " -:- ", S13, " -:- ", T13, " -:- ", U13) -> Residential -:- -:- -:- Geothermal | W13: ="Distribution network for "&G13 -> Distribution network for Residential Geothermal | X13: PJ | Y13: PJ_a
B14: NRG | C14: RESSOL | D14: Solar | F14: =_xlfn.CONCAT(D14, " -:- ", E14) -> Solar -:- | G14: Residential Solar energy | H14: PJ | I14: FX | P14: PRE | Q14: ="FTE_"&C14&"_00" -> FTE_RESSOL_00 | R14: Residential | U14: Solar | V14: =_xlfn.CONCAT( R14, " -:- ", S14, " -:- ", T14, " -:- ", U14) -> Residential -:- -:- -:- Solar | W14: ="Distribution network for "&G14 -> Distribution network for Residential Solar energy | X14: PJ | Y14: PJ_a
B15: NRG | C15: RESPET | D15: Petrol | F15: =_xlfn.CONCAT(D15, " -:- ", E15) -> Petrol -:- | G15: Residential petroleum | H15: PJ | I15: FX | P15: PRE | Q15: ="FTE_"&C15&"_00" -> FTE_RESPET_00 | R15: Residential | U15: Petrol | V15: =_xlfn.CONCAT( R15, " -:- ", S15, " -:- ", T15, " -:- ", U15) -> Residential -:- -:- -:- Petrol | W15: ="Distribution network for "&G15 -> Distribution network for Residential petroleum | X15: PJ | Y15: PJ_a
B16: ENV | C16: RESCO2 | F16: =_xlfn.CONCAT(D16, " -:- ", E16) -> -:- | G16: Residential CO2 emissions | H16: kt | P16: DMD | Q16: =+RES!C7 -> R_DDW-SH_Burner-WOD00 | R16: Residential | S16: Detached Dwellings | T16: Burner | U16: Wood | V16: =_xlfn.CONCAT( R16, " -:- ", S16, " -:- ", T16, " -:- ", U16) -> Residential -:- Detached Dwellings -:- Burner -:- Wood | W16: =+RES!D7 -> Detached dwellings - Heat/Cooling Devices - Burner (Direct Heat) | X16: PJ | Y16: GW
B17: DEM | C17: R_DDW-SH | E17: Space Heating | F17: =_xlfn.CONCAT(D17, " -:- ", E17) -> -:- Space Heating | G17: Detached dwellings - Low Temperature Heat (<100 C), Space Heating | H17: PJ | P17: DMD | Q17: =+RES!C8 -> R_DDW-SH_Burner-LPG00 | R17: Residential | S17: Detached Dwellings | T17: Burner | U17: LPG | V17: =_xlfn.CONCAT( R17, " -:- ", S17, " -:- ", T17, " -:- ", U17) -> Residential -:- Detached Dwellings -:- Burner -:- LPG | W17: =+RES!D8 -> Detached dwellings - Heat/Cooling Devices - Burner (Direct Heat) | X17: PJ | Y17: GW
B18: DEM | C18: R_DDW-WH | E18: Water Heating | F18: =_xlfn.CONCAT(D18, " -:- ", E18) -> -:- Water Heating | G18: Detached dwellings - Low Temperature Heat (<100 C), Water Heating | H18: PJ | P18: DMD | Q18: =+RES!C9 -> R_DDW-SH_Burner-DSL00 | R18: Residential | S18: Detached Dwellings | T18: Burner | U18: Diesel | V18: =_xlfn.CONCAT( R18, " -:- ", S18, " -:- ", T18, " -:- ", U18) -> Residential -:- Detached Dwellings -:- Burner -:- Diesel | W18: =+RES!D9 -> Detached dwellings - Heat/Cooling Devices - Burner (Direct Heat) | X18: PJ | Y18: GW
B19: DEM | C19: R_DDW-CK | E19: Cooking | F19: =_xlfn.CONCAT(D19, " -:- ", E19) -> -:- Cooking | G19: Detached dwellings - Intermediate Heat (100-300 C), Cooking | H19: PJ | P19: DMD | Q19: =+RES!C10 -> R_DDW-SH_Burner-COA00 | R19: Residential | S19: Detached Dwellings | T19: Burner | U19: Coal | V19: =_xlfn.CONCAT( R19, " -:- ", S19, " -:- ", T19, " -:- ", U19) -> Residential -:- Detached Dwellings -:- Burner -:- Coal | W19: =+RES!D10 -> Detached dwellings - Heat/Cooling Devices - Burner (Direct Heat) | X19: PJ | Y19: GW
B20: DEM | C20: R_DDW-RF | E20: Refrigeration | F20: =_xlfn.CONCAT(D20, " -:- ", E20) -> -:- Refrigeration | G20: Detached dwellings - Refrigeration | H20: PJ | P20: DMD | Q20: =+RES!C11 -> R_DDW-SH_OF-WOD00 | R20: Residential | S20: Detached Dwellings | T20: Open Fire | U20: Wood | V20: =_xlfn.CONCAT( R20, " -:- ", S20, " -:- ", T20, " -:- ", U20) -> Residential -:- Detached Dwellings -:- Open Fire -:- Wood | W20: =+RES!D11 -> Detached dwellings - Heat/Cooling Devices - Open Fire | X20: PJ | Y20: GW
B21: DEM | C21: R_DDW-CD | E21: Clothes Drying | F21: =_xlfn.CONCAT(D21, " -:- ", E21) -> -:- Clothes Drying | G21: Detached dwellings - Low Temperature Heat (<100 C), Clothes Drying | H21: PJ | P21: DMD | Q21: =+RES!C12 -> R_DDW-SH_OF-COA00 | R21: Residential | S21: Detached Dwellings | T21: Open Fire | U21: Coal | V21: =_xlfn.CONCAT( R21, " -:- ", S21, " -:- ", T21, " -:- ", U21) -> Residential -:- Detached Dwellings -:- Open Fire -:- Coal | W21: =+RES!D12 -> Detached dwellings - Heat/Cooling Devices - Open Fire | X21: PJ | Y21: GW
B22: DEM | C22: R_DDW-SC | E22: Space Cooling | F22: =_xlfn.CONCAT(D22, " -:- ", E22) -> -:- Space Cooling | G22: Detached dwellings - Space Cooling | H22: PJ | P22: DMD | Q22: =+RES!C13 -> R_DDW-SH_OFWB-COA00 | R22: Residential | S22: Detached Dwellings | T22: Open Fire (with Wetback) | U22: Coal | V22: =_xlfn.CONCAT( R22, " -:- ", S22, " -:- ", T22, " -:- ", U22) -> Residential -:- Detached Dwellings -:- Open Fire (with Wetback) -:- Coal | W22: =+RES!D13 -> Detached dwellings - Heat/Cooling Devices - Open Fire, with Wetback | X22: PJ | Y22: GW
B23: DEM | C23: R_DDW-CW | E23: Clothes Washing | F23: =_xlfn.CONCAT(D23, " -:- ", E23) -> -:- Clothes Washing | G23: Detached dwellings - Low Temperature Heat (<100 C), Clothes Washing | H23: PJ | P23: DMD | Q23: =+RES!C14 -> R_DDW-SH_HP-ELC00 | R23: Residential | S23: Detached Dwellings | T23: Heat Pump | U23: Electricity | V23: =_xlfn.CONCAT( R23, " -:- ", S23, " -:- ", T23, " -:- ", U23) -> Residential -:- Detached Dwellings -:- Heat Pump -:- Electricity | W23: =+RES!D14 -> Detached dwellings - Heat/Cooling Devices - Heat Pump (for Heating) | X23: PJ | Y23: GW
B24: DEM | C24: R_DDW-DW | E24: Dishwashing | F24: =_xlfn.CONCAT(D24, " -:- ", E24) -> -:- Dishwashing | G24: Detached dwellings - Low Temperature Heat (< 100 C), Dishwashers | H24: PJ | P24: DMD | Q24: =+RES!C15 -> R_DDW-SH_RH-ELC00 | R24: Residential | S24: Detached Dwellings | T24: Resistance Heater | U24: Electricity | V24: =_xlfn.CONCAT( R24, " -:- ", S24, " -:- ", T24, " -:- ", U24) -> Residential -:- Detached Dwellings -:- Resistance Heater -:- Electricity | W24: =+RES!D15 -> Detached dwellings - Heat/Cooling Devices - Resistance Heater | X24: PJ | Y24: GW
B25: DEM | C25: R_DDW-LT | E25: Lighting | F25: =_xlfn.CONCAT(D25, " -:- ", E25) -> -:- Lighting | G25: Detached dwellings - Lighting | H25: PJ | P25: DMD | Q25: =+RES!C16 -> R_DDW-WH_OFWB-COA00 | R25: Residential | S25: Detached Dwellings | T25: Open Fire (with Wetback) | U25: Coal | V25: =_xlfn.CONCAT( R25, " -:- ", S25, " -:- ", T25, " -:- ", U25) -> Residential -:- Detached Dwellings -:- Open Fire (with Wetback) -:- Coal | W25: =+RES!D16 -> Detached dwellings - Heat/Cooling Devices - Open Fire, with Wetback | X25: PJ | Y25: GW
B26: DEM | C26: R_DDW-OTH | E26: Electronics and Other Appliances | F26: =_xlfn.CONCAT(D26, " -:- ", E26) -> -:- Electronics and Other Appliances | G26: Detached dwellings - Electronics and Other Electrical Uses | H26: PJ | P26: DMD | Q26: =+RES!C17 -> R_DDW-WH_HWC-SOL00 | R26: Residential | S26: Detached Dwellings | T26: Hot Water Cylinder | U26: Solar | V26: =_xlfn.CONCAT( R26, " -:- ", S26, " -:- ", T26, " -:- ", U26) -> Residential -:- Detached Dwellings -:- Hot Water Cylinder -:- Solar | W26: =+RES!D17 -> Detached dwellings - Heat/Cooling Devices - Hot Water Cylinder | X26: PJ | Y26: GW
B27: DEM | C27: R_DDW-MPS | E27: Motive Power, Stationary | F27: =_xlfn.CONCAT(D27, " -:- ", E27) -> -:- Motive Power, Stationary | G27: Detached dwellings - Motive Power, Stationary | H27: PJ | P27: DMD | Q27: =+RES!C18 -> R_DDW-WH_HWC-ELC00 | R27: Residential | S27: Detached Dwellings | T27: Hot Water Cylinder | U27: Electricity | V27: =_xlfn.CONCAT( R27, " -:- ", S27, " -:- ", T27, " -:- ", U27) -> Residential -:- Detached Dwellings -:- Hot Water Cylinder -:- Electricity | W27: =+RES!D18 -> Detached dwellings - Heat/Cooling Devices - Hot Water Cylinder | X27: PJ | Y27: GW
B28: DEM | C28: R_DDW-MPM | E28: Motive Power, Mobile | F28: =_xlfn.CONCAT(D28, " -:- ", E28) -> -:- Motive Power, Mobile | G28: Detached dwellings - Motive Power, Mobile | H28: PJ | P28: DMD | Q28: =+RES!C19 -> R_DDW-WH_Gasheat-LPG00 | R28: Residential | S28: Detached Dwellings | T28: Gas Heater | U28: LPG | V28: =_xlfn.CONCAT( R28, " -:- ", S28, " -:- ", T28, " -:- ", U28) -> Residential -:- Detached Dwellings -:- Gas Heater -:- LPG | W28: =+RES!D19 -> Detached dwellings - Heat/Cooling Devices - Gas Water Heater | X28: PJ | Y28: GW
... B40: DEM | C40: R_JDW-MPM | E40: Motive Power, Mobile | F40: =_xlfn.CONCAT(D40, " -:- ", E40) -> -:- Motive Power, Mobile | G40: Joined dwellings - Motive Power, Mobile | H40: PJ | P40: DMD | Q40: =+RES!C31 -> R_DDW-LT_CFL-ELC00 | R40: Residential | S40: Detached Dwellings | T40: Lights (Fluorescent) | U40: Electricity | V40: =_xlfn.CONCAT( R40, " -:- ", S40, " -:- ", T40, " -:- ", U40) -> Residential -:- Detached Dwellings -:- Lights (Fluorescent) -:- Electricity | W40: =+RES!D31 -> Detached dwellings - Electronics and Lights - Fluorescent | X40: PJ | Y40: GW
F41: =_xlfn.CONCAT(D41, " -:- ", E41) -> -:- | P41: DMD | Q41: =+RES!C32 -> R_DDW-OTH_Elec-ELC00 | R41: Residential | S41: Detached Dwellings | T41: Electronics and Other Appliances | U41: Electricity | V41: =_xlfn.CONCAT( R41, " -:- ", S41, " -:- ", T41, " -:- ", U41) -> Residential -:- Detached Dwellings -:- Electronics and Other Appliances -:- Electricity | W41: =+RES!D32 -> Detached dwellings - Electronics and Lights - Electronics | X41: PJ | Y41: GW
P42: DMD | Q42: =+RES!C33 -> R_DDW-MPS_Motor-ELC00 | R42: Residential | S42: Detached Dwellings | T42: Stationary Motor | U42: Electricity | V42: =_xlfn.CONCAT( R42, " -:- ", S42, " -:- ", T42, " -:- ", U42) -> Residential -:- Detached Dwellings -:- Stationary Motor -:- Electricity | W42: =+RES!D33 -> Detached dwellings - Stationary Motors - Electric Motor | X42: PJ | Y42: GW
P43: DMD | Q43: =+RES!C34 -> R_DDW-MPM_ICE-PET00 | R43: Residential | S43: Detached Dwellings | T43: Mobile Motor | U43: Petrol | V43: =_xlfn.CONCAT( R43, " -:- ", S43, " -:- ", T43, " -:- ", U43) -> Residential -:- Detached Dwellings -:- Mobile Motor -:- Petrol | W43: =+RES!D34 -> Detached dwellings - Stationary Motors - Internal Combustion (Domestic Use) | X43: PJ | Y43: GW
P44: DMD | Q44: =+RES!C35 -> R_JDW-SH_Burner-LPG00 | R44: Residential | S44: Joined Dwellings | T44: Burner | U44: LPG | V44: =_xlfn.CONCAT( R44, " -:- ", S44, " -:- ", T44, " -:- ", U44) -> Residential -:- Joined Dwellings -:- Burner -:- LPG | W44: =+RES!D35 -> Joined dwellings - Heat/Cooling Devices - Burner (Direct Heat) | X44: PJ | Y44: GW
P45: DMD | Q45: =+RES!C36 -> R_JDW-SH_Burner-DSL00 | R45: Residential | S45: Joined Dwellings | T45: Burner | U45: Diesel | V45: =_xlfn.CONCAT( R45, " -:- ", S45, " -:- ", T45, " -:- ", U45) -> Residential -:- Joined Dwellings -:- Burner -:- Diesel | W45: =+RES!D36 -> Joined dwellings - Heat/Cooling Devices - Burner (Direct Heat) | X45: PJ | Y45: GW
P46: DMD | Q46: =+RES!C37 -> R_JDW-SH_HP-ELC00 | R46: Residential | S46: Joined Dwellings | T46: Heat Pump | U46: Electricity | V46: =_xlfn.CONCAT( R46, " -:- ", S46, " -:- ", T46, " -:- ", U46) -> Residential -:- Joined Dwellings -:- Heat Pump -:- Electricity | W46: =+RES!D37 -> Joined dwellings - Heat/Cooling Devices - Heat Pump (for Heating) | X46: PJ | Y46: GW
P47: DMD | Q47: =+RES!C38 -> R_JDW-SH_RH-ELC00 | R47: Residential | S47: Joined Dwellings | T47: Resistance Heater | U47: Electricity | V47: =_xlfn.CONCAT( R47, " -:- ", S47, " -:- ", T47, " -:- ", U47) -> Residential -:- Joined Dwellings -:- Resistance Heater -:- Electricity | W47: =+RES!D38 -> Joined dwellings - Heat/Cooling Devices - Resistance Heater | X47: PJ | Y47: GW
P48: DMD | Q48: =+RES!C39 -> R_JDW-WH_HWC-SOL00 | R48: Residential | S48: Joined Dwellings | T48: Hot Water Cylinder | U48: Solar | V48: =_xlfn.CONCAT( R48, " -:- ", S48, " -:- ", T48, " -:- ", U48) -> Residential -:- Joined Dwellings -:- Hot Water Cylinder -:- Solar | W48: =+RES!D39 -> Joined dwellings - Heat/Cooling Devices - Hot Water Cylinder | X48: PJ | Y48: GW
P49: DMD | Q49: =+RES!C40 -> R_JDW-WH_HWC-ELC00 | R49: Residential | S49: Joined Dwellings | T49: Hot Water Cylinder | U49: Electricity | V49: =_xlfn.CONCAT( R49, " -:- ", S49, " -:- ", T49, " -:- ", U49) -> Residential -:- Joined Dwellings -:- Hot Water Cylinder -:- Electricity | W49: =+RES!D40 -> Joined dwellings - Heat/Cooling Devices - Hot Water Cylinder | X49: PJ | Y49: GW
P50: DMD | Q50: =+RES!C41 -> R_JDW-WH_Gasheat-LPG00 | R50: Residential | S50: Joined Dwellings | T50: Gas Heater | U50: LPG | V50: =_xlfn.CONCAT( R50, " -:- ", S50, " -:- ", T50, " -:- ", U50) -> Residential -:- Joined Dwellings -:- Gas Heater -:- LPG | W50: =+RES!D41 -> Joined dwellings - Heat/Cooling Devices - Gas Water Heater | X50: PJ | Y50: GW
P51: DMD | Q51: =+RES!C42 -> R_JDW-CK_Appl-ELC00 | R51: Residential | S51: Joined Dwellings | T51: Cooking Element | U51: Electricity | V51: =_xlfn.CONCAT( R51, " -:- ", S51, " -:- ", T51, " -:- ", U51) -> Residential -:- Joined Dwellings -:- Cooking Element -:- Electricity | W51: =+RES!D42 -> Joined dwellings - Heat/Cooling Devices - Cooking Appliances | X51: PJ | Y51: GW
P52: DMD | Q52: =+RES!C43 -> R_JDW-CK_Appl-LPG00 | R52: Residential | S52: Joined Dwellings | T52: Cooking Element | U52: LPG | V52: =_xlfn.CONCAT( R52, " -:- ", S52, " -:- ", T52, " -:- ", U52) -> Residential -:- Joined Dwellings -:- Cooking Element -:- LPG | W52: =+RES!D43 -> Joined dwellings - Heat/Cooling Devices - Cooking Appliances | X52: PJ | Y52: GW
P53: DMD | Q53: =+RES!C44 -> R_JDW-RF_Refriger-ELC00 | R53: Residential | S53: Joined Dwellings | T53: Refrigerator | U53: Electricity | V53: =_xlfn.CONCAT( R53, " -:- ", S53, " -:- ", T53, " -:- ", U53) -> Residential -:- Joined Dwellings -:- Refrigerator -:- Electricity | W53: =+RES!D44 -> Joined dwellings - Heat/Cooling Devices - Refrigeration systems | X53: PJ | Y53: GW
... P63: DMD | Q63: =+RES!C54 -> R_JDW-MPM_ICE-PET00 | R63: Residential | S63: Joined Dwellings | T63: Mobile Motor | U63: Petrol | V63: =_xlfn.CONCAT( R63, " -:- ", S63, " -:- ", T63, " -:- ", U63) -> Residential -:- Joined Dwellings -:- Mobile Motor -:- Petrol | W63: =+RES!D54 -> Joined dwellings - Stationary Motors - Internal Combustion (Domestic Use) | X63: PJ | Y63: GW

Sheet RES_fuel_dem
B1: Fuel supply to residential sector
E3: ~FI_T
C4: TechName | D4: Comm-IN | E4: Comm-OUT | F4: Share-I~UP | G4: STOCK | H4: EFF | I4: LIFE | J4: INVCOST | K4: FIXOM | L4: VAROM
C5: *Technology Name | D5: Input Commodity | E5: Output Commodity | F5: Input Share | G5: Existing Installed Capacity | H5: Efficiency | I5: Lifetime | J5: Capital costs | K5: Fixed O&M | L5: Variable O&M
C6: *Units | G6: PJa | I6: Years | J6: MNZD/Pja | K6: MNZD/Pja | L6: MNZD/PJ
C7: =RES_techs_coms!Q8 -> FTE_RESCOA_00 | D7: COA | E7: =MID(C7,5,6) -> RESCOA | F7: 1 | H7: 1 | I7: 100
D8: COL | F8: 1
C9: =RES_techs_coms!Q9 -> FTE_RESNGA_00 | D9: NGA | E9: =MID(C9,5,6) -> RESNGA | H9: 1 | I9: 100 | L9: 25
C10: =RES_techs_coms!Q10 -> FTE_RESLPG_00 | D10: LPG | E10: =MID(C10,5,6) -> RESLPG | H10: 1 | I10: 100
C11: =RES_techs_coms!Q11 -> FTE_RESDSL_00 | D11: DSL | E11: =MID(C11,5,6) -> RESDSL | H11: 1 | I11: 100 | L11: 0.92
C12: =RES_techs_coms!Q12 -> FTE_RESWOD_00 | D12: WOD | E12: =MID(C12,5,6) -> RESWOD | H12: 1 | I12: 100 | L12: 10
C13: =RES_techs_coms!Q13 -> FTE_RESGEO_00 | D13: GEO | E13: =MID(C13,5,6) -> RESGEO | H13: 1 | I13: 100
C14: =RES_techs_coms!Q14 -> FTE_RESSOL_00 | D14: SOL | E14: =MID(C14,5,6) -> RESSOL | H14: 1 | I14: 100
C15: =RES_techs_coms!Q15 -> FTE_RESPET_00 | D15: PET | E15: =MID(C15,5,6) -> RESPET | H15: 1 | I15: 100 | L15: 0.92
C18: ~FI_T
C19: CommName | D19: Demand~2018 | E19: Demand~2020 | F19: Demand~2025 | G19: Demand~2030 | H19: Demand~2040 | I19: Demand~2050 | J19: Demand~2060
C20: =RES_techs_coms!C17 -> R_DDW-SH | D20: =ROUNDDOWN(SUMIF(RES!$F$7:$F$62,C20,RES!$N$7:$N$62),3) -> 10.134 | E20: =+D20 -> 10.134 | F20: =+E20 -> 10.134 | G20: =+F20 -> 10.134 | H20: =+G20 -> 10.134 | I20: =+H20 -> 10.134 | J20: =+I20 -> 10.134
C21: =RES_techs_coms!C18 -> R_DDW-WH | D21: =ROUNDDOWN(SUMIF(RES!$F$7:$F$62,C21,RES!$N$7:$N$62),3) -> 3.324 | E21: =+D21 -> 3.324 | F21: =+E21 -> 3.324 | G21: =+F21 -> 3.324 | H21: =+G21 -> 3.324 | I21: =+H21 -> 3.324 | J21: =+I21 -> 3.324
C22: =RES_techs_coms!C19 -> R_DDW-CK | D22: =ROUNDDOWN(SUMIF(RES!$F$7:$F$62,C22,RES!$N$7:$N$62),3) -> 0.61 | E22: =+D22 -> 0.61 | F22: =+E22 -> 0.61 | G22: =+F22 -> 0.61 | H22: =+G22 -> 0.61 | I22: =+H22 -> 0.61 | J22: =+I22 -> 0.61
C23: =RES_techs_coms!C20 -> R_DDW-RF | D23: =ROUNDDOWN(SUMIF(RES!$F$7:$F$62,C23,RES!$N$7:$N$62),3) -> 1.801 | E23: =+D23 -> 1.801 | F23: =+E23 -> 1.801 | G23: =+F23 -> 1.801 | H23: =+G23 -> 1.801 | I23: =+H23 -> 1.801 | J23: =+I23 -> 1.801
C24: =RES_techs_coms!C21 -> R_DDW-CD | D24: =ROUNDDOWN(SUMIF(RES!$F$7:$F$62,C24,RES!$N$7:$N$62),3) -> 0.052 | E24: =+D24 -> 0.052 | F24: =+E24 -> 0.052 | G24: =+F24 -> 0.052 | H24: =+G24 -> 0.052 | I24: =+H24 -> 0.052 | J24: =+I24 -> 0.052
C25: =RES_techs_coms!C22 -> R_DDW-SC | D25: =ROUNDDOWN(SUMIF(RES!$F$7:$F$62,C25,RES!$N$7:$N$62),3) -> 0.371 | E25: =+D25 -> 0.371 | F25: =+E25 -> 0.371 | G25: =+F25 -> 0.371 | H25: =+G25 -> 0.371 | I25: =+H25 -> 0.371 | J25: =+I25 -> 0.371
C26: =RES_techs_coms!C23 -> R_DDW-CW | D26: =ROUNDDOWN(SUMIF(RES!$F$7:$F$62,C26,RES!$N$7:$N$62),3) -> 0.169 | E26: =+D26 -> 0.169 | F26: =+E26 -> 0.169 | G26: =+F26 -> 0.169 | H26: =+G26 -> 0.169 | I26: =+H26 -> 0.169 | J26: =+I26 -> 0.169
C27: =RES_techs_coms!C24 -> R_DDW-DW | D27: =ROUNDDOWN(SUMIF(RES!$F$7:$F$62,C27,RES!$N$7:$N$62),3) -> 0.056 | E27: =+D27 -> 0.056 | F27: =+E27 -> 0.056 | G27: =+F27 -> 0.056 | H27: =+G27 -> 0.056 | I27: =+H27 -> 0.056 | J27: =+I27 -> 0.056
C28: =RES_techs_coms!C25 -> R_DDW-LT | D28: =ROUNDDOWN(SUMIF(RES!$F$7:$F$62,C28,RES!$N$7:$N$62),3) -> 0.174 | E28: =+D28 -> 0.174 | F28: =+E28 -> 0.174 | G28: =+F28 -> 0.174 | H28: =+G28 -> 0.174 | I28: =+H28 -> 0.174 | J28: =+I28 -> 0.174
C29: =RES_techs_coms!C26 -> R_DDW-OTH | D29: =ROUNDDOWN(SUMIF(RES!$F$7:$F$62,C29,RES!$N$7:$N$62),3) -> 0.654 | E29: =+D29 -> 0.654 | F29: =+E29 -> 0.654 | G29: =+F29 -> 0.654 | H29: =+G29 -> 0.654 | I29: =+H29 -> 0.654 | J29: =+I29 -> 0.654
C30: =RES_techs_coms!C27 -> R_DDW-MPS | D30: =ROUNDDOWN(SUMIF(RES!$F$7:$F$62,C30,RES!$N$7:$N$62),3) -> 0.051 | E30: =+D30 -> 0.051 | F30: =+E30 -> 0.051 | G30: =+F30 -> 0.051 | H30: =+G30 -> 0.051 | I30: =+H30 -> 0.051 | J30: =+I30 -> 0.051
C31: =RES_techs_coms!C28 -> R_DDW-MPM | D31: =ROUNDDOWN(SUMIF(RES!$F$7:$F$62,C31,RES!$N$7:$N$62),3) -> 0 | E31: =+D31 -> 0 | F31: =+E31 -> 0 | G31: =+F31 -> 0 | H31: =+G31 -> 0 | I31: =+H31 -> 0 | J31: =+I31 -> 0
... C43: =RES_techs_coms!C40 -> R_JDW-MPM | D43: =ROUNDDOWN(SUMIF(RES!$F$7:$F$62,C43,RES!$N$7:$N$62),3) -> 0 | E43: =+D43 -> 0 | F43: =+E43 -> 0 | G43: =+F43 -> 0 | H43: =+G43 -> 0 | I43: =+H43 -> 0 | J43: =+I43 -> 0

Sheet RES
F4: ~FI_T
C5: TechName | D5: *TechDesc | E5: Comm-IN | F5: Comm-OUT | G5: EFF | H5: AFA | I5: AFA~LO | J5: NCAP_TLIFE | K5: CAP2ACT | L5: NCAP_PASTI | M5: *NCAP_PASTI | N5: ACT_BND | O5: INVCOST | P5: FIXOM | Q5: NCAP_BND | R5: NCAP_BND~0 | S5: FLO_MARK | T5: FLO_MARK~2030 | U5: FLO_MARK~2050 | V5: FLO_MARK~0
C6: \I: Technology Name | D6: Technology Description | E6: Input Commodity | F6: Output Commodity | G6: Efficiency | H6: Annual Availability Factor | I6: Annual Availability Factor | J6: Lifetime of Process | K6: Capacity to Activity Factor | L6: Existing Installed Capacity in Pja | N6: Bound on activity of a process | O6: Investment cost | P6: O&M costs
C7: =+[6]SI!J2 -> R_DDW-SH_Burner-WOD00 | D7: =+[6]SI!A2&" - "&[6]SI!C2&" - "&[6]SI!D2 -> Detached dwellings - Heat/Cooling Devices - Burner (Direct Heat) | E7: =+[6]SI!K2 -> RESWOD | F7: =+[6]SI!L2 -> R_DDW-SH | G7: =+[6]SI!O2 -> 0.6 | H7: =+[6]SI!Q2 -> 0.0821 | I7: =+IF(L7>0.01,H7*0.75,0) -> 0.061575 | J7: =+[6]SI!P2 -> 20 | K7: 31.536 | L7: =+N7/K7/H7 -> 0.63556873 | N7: 1.6455546 | O7: 373 | S7: =+N7/SUM(N7:N15) -> 0.16236589 | V7: 5
C8: =+[6]SI!J3 -> R_DDW-SH_Burner-LPG00 | D8: =+[6]SI!A3&" - "&[6]SI!C3&" - "&[6]SI!D3 -> Detached dwellings - Heat/Cooling Devices - Burner (Direct Heat) | E8: =+[6]SI!K3 -> RESLPG | F8: =+[6]SI!L3 -> R_DDW-SH | G8: =+[6]SI!O3 -> 0.8 | H8: =+[6]SI!Q3 -> 0.0821 | I8: =+IF(L8>0.01,H8*0.75,0) -> 0.061575 | J8: =+[6]SI!P3 -> 20 | K8: 31.536 | L8: =+N8/K8/H8 -> 0.12896287 | N8: 0.33389849 | O8: =+[6]SI!U3 -> 1260 | P8: =+[6]SI!V3 -> 150
C9: =+[6]SI!J4 -> R_DDW-SH_Burner-DSL00 | D9: =+[6]SI!A4&" - "&[6]SI!C4&" - "&[6]SI!D4 -> Detached dwellings - Heat/Cooling Devices - Burner (Direct Heat) | E9: =+[6]SI!K4 -> RESDSL | F9: =+[6]SI!L4 -> R_DDW-SH | G9: =+[6]SI!O4 -> 0.8 | H9: =+[6]SI!Q4 -> 0.0045 | I9: =+IF(L9>0.01,H9*0.75,0) -> 0.003375 | J9: 5 | K9: 31.536 | L9: =+N9/K9/H9 -> 0.21598682 | N9: 0.030651122 | Q9: 0 | R9: 5
C10: =+[6]SI!J5 -> R_DDW-SH_Burner-COA00 | D10: =+[6]SI!A5&" - "&[6]SI!C5&" - "&[6]SI!D5 -> Detached dwellings - Heat/Cooling Devices - Burner (Direct Heat) | E10: =+[6]SI!K5 -> RESCOA | F10: =+[6]SI!L5 -> R_DDW-SH | G10: =+[6]SI!O5 -> 0.6 | H10: =+[6]SI!Q5 -> 0.0045 | I10: =+IF(L10>0.01,H10*0.75,0) -> 0.003375 | J10: 5 | K10: 31.536 | L10: =+N10/K10/H10 -> 0.1414572 | N10: 0.020074474 | Q10: 0 | R10: 5
C11: =+[6]SI!J6 -> R_DDW-SH_OF-WOD00 | D11: =+[6]SI!A6&" - "&[6]SI!C6&" - "&[6]SI!D6 -> Detached dwellings - Heat/Cooling Devices - Open Fire | E11: =+[6]SI!K6 -> RESWOD | F11: =+[6]SI!L6 -> R_DDW-SH | G11: =+[6]SI!O6 -> 0.06 | H11: =+[6]SI!Q6 -> 0.0821 | I11: =+IF(L11>0.01,H11*0.75,0) -> 0 | J11: =+[6]SI!P6 -> 50 | K11: 31.536 | L11: =+N11/K11/H11 -> 0.0019528039 | N11: 0.0050560155 | Q11: 0 | R11: 5
C12: =+[6]SI!J7 -> R_DDW-SH_OF-COA00 | D12: =+[6]SI!A7&" - "&[6]SI!C7&" - "&[6]SI!D7 -> Detached dwellings - Heat/Cooling Devices - Open Fire | E12: =+[6]SI!K7 -> RESCOA | F12: =+[6]SI!L7 -> R_DDW-SH | G12: =+[6]SI!O7 -> 0.06 | H12: =+[6]SI!Q7 -> 0.0821 | I12: =+IF(L12>0.01,H12*0.75,0) -> 0 | J12: =+[6]SI!P7 -> 50 | K12: 31.536 | L12: =+N12/K12/H12 -> 0.0014953223 | N12: 0.0038715473 | Q12: 0 | R12: 5
C13: =+[6]SI!J8 -> R_DDW-SH_OFWB-COA00 | D13: =+[6]SI!A8&" - "&[6]SI!C8&" - "&[6]SI!D8 -> Detached dwellings - Heat/Cooling Devices - Open Fire, with Wetback | E13: =+[6]SI!K8 -> RESCOA | F13: =+[6]SI!L8 -> R_DDW-SH | G13: =+[6]SI!O8 -> 0.06 | H13: =+[6]SI!Q8 -> 0.0821 | I13: =+IF(L13>0.01,H13*0.75,0) -> 0 | J13: =+[6]SI!P8 -> 50 | K13: 31.536 | L13: =+N13/K13/H13 -> 0.00017711276 | N13: 0.00045856365 | Q13: 0 | R13: 5
C14: =+[6]SI!J9 -> R_DDW-SH_HP-ELC00 | D14: =+[6]SI!A9&" - "&[6]SI!C9&" - "&[6]SI!D9 -> Detached dwellings - Heat/Cooling Devices - Heat Pump (for Heating) | E14: =+[6]SI!K9 -> RESELC | F14: =+[6]SI!L9 -> R_DDW-SH | G14: =+[6]SI!O9 -> 3.75 | H14: =+[6]SI!Q9 -> 0.0821 | I14: =+IF(L14>0.01,H14*0.75,0) -> 0.061575 | J14: =+[6]SI!P9 -> 12 | K14: 31.536 | L14: =+N14/K14/H14 -> 2.5591375 | N14: 6.6258772 | O14: =+[6]SI!U9 -> 557.90698
C15: =+[6]SI!J10 -> R_DDW-SH_RH-ELC00 | D15: =+[6]SI!A10&" - "&[6]SI!C10&" - "&[6]SI!D10 -> Detached dwellings - Heat/Cooling Devices - Resistance Heater | E15: =+[6]SI!K10 -> RESELC | F15: =+[6]SI!L10 -> R_DDW-SH | G15: =+[6]SI!O10 -> 1 | H15: =+[6]SI!Q10 -> 0.0821 | I15: =+IF(L15>0.01,H15*0.75,0) -> 0.061575 | J15: =+[6]SI!P10 -> 5 | K15: 31.536 | L15: =+N15/K15/H15 -> 0.56753642 | N15: 1.4694117 | O15: =+[6]SI!U10 -> 24
