Workbook

Sheet Veda
G1: 1-3
D2: ="~Inputcell: "&_xlfn.TEXTJOIN(",",TRUE,G1:DM1) -> ~Inputcell: 1-3
D3: 4
D5: =VLOOKUP(D3,$C$9:$E$999,2,FALSE) -> ts_012 | E5: =VLOOKUP(D3,$C$9:$E$999,3,FALSE) -> nz
B7: ~Scenmap
A8: priority | B8: scen | C8: case_no | D8: timeslice | E8: climate
A9: 5 | B9: =VLOOKUP(E9,$S$9:$T$15,2,FALSE)&"."&VLOOKUP(D9,$P$9:$Q$24,2,FALSE) -> 1tui.j12 | C9: 1 | D9: ts_012 | E9: tui | G9: Limit warming to 1.5°C (>50%) with no or limited overshoot | O9: 1 | P9: ts_annual | Q9: kAnn | R9: 1 | S9: kea | T9: 2kea
A10: 5 | B10: =VLOOKUP(E10,$S$9:$T$15,2,FALSE)&"."&VLOOKUP(D10,$P$9:$Q$24,2,FALSE) -> 2kea.j12 | C10: =C9+1 -> 2 | D10: ts_012 | E10: kea | G10: Limit warming to 1.5°C (>67%) with high overshoot | O10: 2 | P10: ts_12t | Q10: k12 | R10: 1 | S10: tui | T10: 1tui
A11: 5 | B11: =VLOOKUP(E11,$S$9:$T$15,2,FALSE)&"."&VLOOKUP(D11,$P$9:$Q$24,2,FALSE) -> 0bas.j12 | C11: =C10+1 -> 3 | D11: ts_012 | E11: bas | G11: Limit warming to 2°C (>67%) with higher action post-2030 | O11: 3 | P11: ts_012 | Q11: j12 | R11: 1 | S11: bas | T11: 0bas
A12: 5 | B12: =VLOOKUP(E12,$S$9:$T$15,2,FALSE)&"."&VLOOKUP(D12,$P$9:$Q$24,2,FALSE) -> 3nz.j12 | C12: =C11+1 -> 4 | D12: ts_012 | E12: nz | G12: Limit warming to 2°C (>50%) with immediate action | O12: 4 | P12: ts_024 | Q12: i24 | R12: 1 | S12: nz | T12: 3nz
A13: 5 | B13: =VLOOKUP(E13,$S$9:$T$15,2,FALSE)&"."&VLOOKUP(D13,$P$9:$Q$24,2,FALSE) -> a 3 deg.kAnn | C13: =C12+1 -> 5 | D13: =VLOOKUP(R13,$O$9:$P$22,2,FALSE) -> ts_annual | E13: C7 | G13: Likely above 3°C warming with limited mitigation | O13: 5 | P13: ts_048 | Q13: h48 | R13: 1 | S13: C7 | T13: a 3 deg
A14: 5 | B14: =VLOOKUP(E14,$S$9:$T$15,2,FALSE)&"."&VLOOKUP(D14,$P$9:$Q$24,2,FALSE) -> 1tui.k12 | C14: =C13+1 -> 6 | D14: =VLOOKUP(R14,$O$9:$P$22,2,FALSE) -> ts_12t | E14: =E9 -> tui | O14: 6 | P14: ts_064 | Q14: g64 | R14: =R9+1 -> 2
A15: 5 | B15: =VLOOKUP(E15,$S$9:$T$15,2,FALSE)&"."&VLOOKUP(D15,$P$9:$Q$24,2,FALSE) -> 2kea.k12 | C15: =C14+1 -> 7 | D15: =VLOOKUP(R15,$O$9:$P$22,2,FALSE) -> ts_12t | E15: =E10 -> kea | O15: 7 | P15: ts_096P50 | Q15: f96p50 | R15: =R10+1 -> 2
A16: 5 | B16: =VLOOKUP(E16,$S$9:$T$15,2,FALSE)&"."&VLOOKUP(D16,$P$9:$Q$24,2,FALSE) -> 0bas.k12 | C16: =C15+1 -> 8 | D16: =VLOOKUP(R16,$O$9:$P$22,2,FALSE) -> ts_12t | E16: =E11 -> bas | O16: 8 | P16: ts_096P10 | Q16: f96p10 | R16: =R11+1 -> 2
A17: 5 | B17: =VLOOKUP(E17,$S$9:$T$15,2,FALSE)&"."&VLOOKUP(D17,$P$9:$Q$24,2,FALSE) -> 3nz.k12 | C17: =C16+1 -> 9 | D17: =VLOOKUP(R17,$O$9:$P$22,2,FALSE) -> ts_12t | E17: =E12 -> nz | O17: 9 | P17: ts_096P90 | Q17: f96p90 | R17: =R12+1 -> 2
A18: 5 | B18: =VLOOKUP(E18,$S$9:$T$15,2,FALSE)&"."&VLOOKUP(D18,$P$9:$Q$24,2,FALSE) -> a 3 deg.k12 | C18: =C17+1 -> 10 | D18: =VLOOKUP(R18,$O$9:$P$22,2,FALSE) -> ts_12t | E18: =E13 -> C7 | O18: 10 | P18: s1p1v1_d | Q18: e3d | R18: =R13+1 -> 2
A19: 5 | B19: =VLOOKUP(E19,$S$9:$T$15,2,FALSE)&"."&VLOOKUP(D19,$P$9:$Q$24,2,FALSE) -> 1tui.j12 | C19: =C18+1 -> 11 | D19: =VLOOKUP(R19,$O$9:$P$22,2,FALSE) -> ts_012 | E19: =E14 -> tui | O19: 11 | P19: s3p3v3_d | Q19: d9d | R19: =R14+1 -> 3
A20: 5 | B20: =VLOOKUP(E20,$S$9:$T$15,2,FALSE)&"."&VLOOKUP(D20,$P$9:$Q$24,2,FALSE) -> 2kea.j12 | C20: =C19+1 -> 12 | D20: =VLOOKUP(R20,$O$9:$P$22,2,FALSE) -> ts_012 | E20: =E15 -> kea | O20: 12 | P20: s5p5v5_d | Q20: c15d | R20: =R15+1 -> 3
A21: 5 | B21: =VLOOKUP(E21,$S$9:$T$15,2,FALSE)&"."&VLOOKUP(D21,$P$9:$Q$24,2,FALSE) -> 0bas.j12 | C21: =C20+1 -> 13 | D21: =VLOOKUP(R21,$O$9:$P$22,2,FALSE) -> ts_012 | E21: =E16 -> bas | O21: 13 | P21: s2_w | Q21: b2w | R21: =R16+1 -> 3
A22: 5 | B22: =VLOOKUP(E22,$S$9:$T$15,2,FALSE)&"."&VLOOKUP(D22,$P$9:$Q$24,2,FALSE) -> 3nz.j12 | C22: =C21+1 -> 14 | D22: =VLOOKUP(R22,$O$9:$P$22,2,FALSE) -> ts_012 | E22: =E17 -> nz | O22: 14 | P22: s2_w_p2_d | Q22: a2w2d | R22: =R17+1 -> 3
A23: 5 | B23: =VLOOKUP(E23,$S$9:$T$15,2,FALSE)&"."&VLOOKUP(D23,$P$9:$Q$24,2,FALSE) -> a 3 deg.j12 | C23: =C22+1 -> 15 | D23: =VLOOKUP(R23,$O$9:$P$22,2,FALSE) -> ts_012 | E23: =E18 -> C7 | R23: =R18+1 -> 3
A24: 5 | B24: =VLOOKUP(E24,$S$9:$T$15,2,FALSE)&"."&VLOOKUP(D24,$P$9:$Q$24,2,FALSE) -> 1tui.i24 | C24: =C23+1 -> 16 | D24: =VLOOKUP(R24,$O$9:$P$22,2,FALSE) -> ts_024 | E24: =E19 -> tui | R24: =R19+1 -> 4
A25: 5 | B25: =VLOOKUP(E25,$S$9:$T$15,2,FALSE)&"."&VLOOKUP(D25,$P$9:$Q$24,2,FALSE) -> 2kea.i24 | C25: =C24+1 -> 17 | D25: =VLOOKUP(R25,$O$9:$P$22,2,FALSE) -> ts_024 | E25: =E20 -> kea | R25: =R20+1 -> 4
A26: 5 | B26: =VLOOKUP(E26,$S$9:$T$15,2,FALSE)&"."&VLOOKUP(D26,$P$9:$Q$24,2,FALSE) -> 0bas.i24 | C26: =C25+1 -> 18 | D26: =VLOOKUP(R26,$O$9:$P$22,2,FALSE) -> ts_024 | E26: =E21 -> bas | R26: =R21+1 -> 4
A27: 5 | B27: =VLOOKUP(E27,$S$9:$T$15,2,FALSE)&"."&VLOOKUP(D27,$P$9:$Q$24,2,FALSE) -> 3nz.i24 | C27: =C26+1 -> 19 | D27: =VLOOKUP(R27,$O$9:$P$22,2,FALSE) -> ts_024 | E27: =E22 -> nz | R27: =R22+1 -> 4
A28: 5 | B28: =VLOOKUP(E28,$S$9:$T$15,2,FALSE)&"."&VLOOKUP(D28,$P$9:$Q$24,2,FALSE) -> a 3 deg.i24 | C28: =C27+1 -> 20 | D28: =VLOOKUP(R28,$O$9:$P$22,2,FALSE) -> ts_024 | E28: =E23 -> C7 | R28: =R23+1 -> 4
A29: 5 | B29: =VLOOKUP(E29,$S$9:$T$15,2,FALSE)&"."&VLOOKUP(D29,$P$9:$Q$24,2,FALSE) -> 1tui.h48 | C29: =C28+1 -> 21 | D29: =VLOOKUP(R29,$O$9:$P$22,2,FALSE) -> ts_048 | E29: =E24 -> tui | R29: =R24+1 -> 5
A30: 5 | B30: =VLOOKUP(E30,$S$9:$T$15,2,FALSE)&"."&VLOOKUP(D30,$P$9:$Q$24,2,FALSE) -> 2kea.h48 | C30: =C29+1 -> 22 | D30: =VLOOKUP(R30,$O$9:$P$22,2,FALSE) -> ts_048 | E30: =E25 -> kea | R30: =R25+1 -> 5
A31: 5 | B31: =VLOOKUP(E31,$S$9:$T$15,2,FALSE)&"."&VLOOKUP(D31,$P$9:$Q$24,2,FALSE) -> 0bas.h48 | C31: =C30+1 -> 23 | D31: =VLOOKUP(R31,$O$9:$P$22,2,FALSE) -> ts_048 | E31: =E26 -> bas | R31: =R26+1 -> 5
A32: 5 | B32: =VLOOKUP(E32,$S$9:$T$15,2,FALSE)&"."&VLOOKUP(D32,$P$9:$Q$24,2,FALSE) -> 3nz.h48 | C32: =C31+1 -> 24 | D32: =VLOOKUP(R32,$O$9:$P$22,2,FALSE) -> ts_048 | E32: =E27 -> nz | R32: =R27+1 -> 5
A33: 5 | B33: =VLOOKUP(E33,$S$9:$T$15,2,FALSE)&"."&VLOOKUP(D33,$P$9:$Q$24,2,FALSE) -> a 3 deg.h48 | C33: =C32+1 -> 25 | D33: =VLOOKUP(R33,$O$9:$P$22,2,FALSE) -> ts_048 | E33: =E28 -> C7 | R33: =R28+1 -> 5
A34: 5 | B34: =VLOOKUP(E34,$S$9:$T$15,2,FALSE)&"."&VLOOKUP(D34,$P$9:$Q$24,2,FALSE) -> 1tui.g64 | C34: =C33+1 -> 26 | D34: =VLOOKUP(R34,$O$9:$P$22,2,FALSE) -> ts_064 | E34: =E29 -> tui | R34: =R29+1 -> 6
... A78: 5 | B78: =VLOOKUP(E78,$S$9:$T$15,2,FALSE)&"."&VLOOKUP(D78,$P$9:$Q$24,2,FALSE) -> a 3 deg.a2w2d | C78: =C77+1 -> 70 | D78: =VLOOKUP(R78,$O$9:$P$22,2,FALSE) -> s2_w_p2_d | E78: =E73 -> C7 | R78: =R73+1 -> 14

Sheet kea-tui
A1: =VLOOKUP(Veda!$E$5,$E$1:$F$4,2,FALSE) -> kea | E1: kea | F1: =E1 -> kea | J1: kea | K1: kea | L1: kea | M1: kea | N1: kea | O1: kea | P1: kea | Q1: tui | R1: tui | S1: tui | T1: tui | U1: tui | V1: tui | AE1: kea | AF1: kea | AG1: kea | AH1: kea | AI1: kea | AJ1: kea | AK1: tui | AL1: tui | AM1: tui | AN1: tui | AO1: tui | AP1: tui | AZ1: kea | BA1: kea | BB1: kea | BC1: kea | BD1: kea | BE1: kea | BF1: kea | BG1: kea | BH1: kea | BI1: kea | BJ1: kea | BK1: tui | BL1: tui | BM1: tui | BN1: tui | BO1: tui | BP1: tui | BQ1: tui | BR1: tui | BS1: tui | BT1: tui | BU1: tui
E2: tui | F2: =E2 -> tui | J2: 2015 | K2: 0 | L2: 2018 | M2: 2020 | N2: 2030 | O2: 2040 | P2: 2050 | Q2: 2015 | R2: 2018 | S2: 2021 | T2: 2030 | U2: 2040 | V2: 2050 | AE2: 2015 | AF2: 0 | AG2: 2018 | AH2: 2030 | AI2: 2040 | AJ2: 2050 | AK2: 2015 | AL2: 0 | AM2: 2018 | AN2: 2030 | AO2: 2040 | AP2: 2050 | AZ2: 0 | BA2: 2018 | BB2: 2020 | BC2: 2025 | BD2: 2030 | BE2: 2035 | BF2: 2040 | BG2: 2045 | BH2: 2050 | BI2: 2055 | BJ2: 2060 | BK2: 0 | BL2: 2018 | BM2: 2020 | BN2: 2025 | BO2: 2030 | BP2: 2035 | BQ2: 2040 | BR2: 2045 | BS2: 2050 | BT2: 2055 | BU2: 2060
E3: bas | F3: tui
E4: nz | F4: kea
C6: ~TFM_DINS-TS | X6: ~TFM_DINS-TS | AR6: ~TFM_DINS-TS
C7: region | D7: attribute | E7: process | F7: commodity_group | G7: commodity | H7: lim_type | I7: currency | J7: =IF($A$1=J1,J2,"*"&COLUMN()) -> 2015 | K7: =IF($A$1=K1,K2,"*"&COLUMN()) -> 0 | L7: =IF($A$1=L1,L2,"*"&COLUMN()) -> 2018 | M7: =IF($A$1=M1,M2,"*"&COLUMN()) -> 2020 | N7: =IF($A$1=N1,N2,"*"&COLUMN()) -> 2030 | O7: =IF($A$1=O1,O2,"*"&COLUMN()) -> 2040 | P7: =IF($A$1=P1,P2,"*"&COLUMN()) -> 2050 | Q7: =IF($A$1=Q1,Q2,"*"&COLUMN()) -> *17 | ... V7: =IF($A$1=V1,V2,"*"&COLUMN()) -> *22 | X7: region | Y7: attribute | Z7: process | AA7: commodity_group | AB7: commodity | AC7: lim_type | AD7: currency | AE7: =IF($A$1=AE1,AE2,"*"&COLUMN()) -> 2015 | AF7: =IF($A$1=AF1,AF2,"*"&COLUMN()) -> 0 | AG7: =IF($A$1=AG1,AG2,"*"&COLUMN()) -> 2018 | AH7: =IF($A$1=AH1,AH2,"*"&COLUMN()) -> 2030 | AI7: =IF($A$1=AI1,AI2,"*"&COLUMN()) -> 2040 | AJ7: =IF($A$1=AJ1,AJ2,"*"&COLUMN()) -> 2050 | AK7: =IF($A$1=AK1,AK2,"*"&COLUMN()) -> *37 | AL7: =IF($A$1=AL1,AL2,"*"&COLUMN()) -> *38 | ... AP7: =IF($A$1=AP1,AP2,"*"&COLUMN()) -> *42 | AR7: region | AS7: attribute | AT7: process | AU7: commodity_group | AV7: commodity | AW7: lim_type | AX7: other_indexes | AY7: currency | AZ7: =IF($A$1=AZ1,AZ2,"*"&COLUMN()) -> 0 | BA7: =IF($A$1=BA1,BA2,"*"&COLUMN()) -> 2018 | BB7: =IF($A$1=BB1,BB2,"*"&COLUMN()) -> 2020 | BC7: =IF($A$1=BC1,BC2,"*"&COLUMN()) -> 2025 | BD7: =IF($A$1=BD1,BD2,"*"&COLUMN()) -> 2030 | BE7: =IF($A$1=BE1,BE2,"*"&COLUMN()) -> 2035 | BF7: =IF($A$1=BF1,BF2,"*"&COLUMN()) -> 2040 | BG7: =IF($A$1=BG1,BG2,"*"&COLUMN()) -> 2045 | ... BU7: =IF($A$1=BU1,BU2,"*"&COLUMN()) -> *73
C8: NI | D8: ACT_EFF | E8: ADCF-IRG-Irg-ELC | F8: ACT | L8: 0.7 | R8: 0.7 | X8: NI | Y8: ACT_EFF | Z8: T_C_CBEVELC | AA8: ACT | AG8: 1.3286636 | AH8: 1.1547045 | AJ8: 1.2533056 | AM8: 1.3286636 | AN8: 1.152396 | AP8: 1.2522726 | AR8: NI | AS8: ACT_BND | AT8: REFEOIL00 | AW8: UP | AZ8: 5 | BF8: 0
C9: NI | D9: ACT_EFF | E9: ADCF-IRG-IrgVSD-ELC | F9: ACT | L9: 0.83 | R9: 0.83 | X9: NI | Y9: ACT_EFF | Z9: T_C_CFCH2R | AA9: ACT | AG9: 0.73529412 | AM9: 0.73529412 | AR9: NI | AS9: COM_PROJ | AV9: ADCF-IRG | BB9: 0.14009922 | BC9: 0.13075246 | BD9: 0.12035304 | BE9: 0.1104008 | BF9: 0.10092396 | BG9: 0.092260618 | BH9: 0.084340938 | BI9: 0.077101086 | BJ9: 0.070482704 | BM9: 0.143098 | BN9: 0.139567 | BO9: 0.13087 | BP9: 0.122715 | BQ9: 0.116509 | BR9: 0.111998 | BS9: 0.107662 | BT9: 0.103493 | BU9: 0.099486
C10: NI | D10: ACT_EFF | E10: ADCF-LIG--ELC | F10: ACT | L10: 0.45 | R10: 0.45 | X10: NI | Y10: ACT_EFF | Z10: T_C_CHYBDSL | AA10: ACT | AG10: 0.34633084 | AH10: 0.37718159 | AJ10: 0.40252295 | AM10: 0.34633084 | AN10: 0.36952603 | AP10: 0.36682985 | AR10: NI | AS10: COM_PROJ | AV10: ADCF-LIG | BB10: 0.006888452 | BC10: 0.0066939614 | BD10: 0.0064807409 | BE10: 0.0062527932 | BF10: 0.0060121579 | BG10: 0.0057807834 | BH10: 0.0055583132 | BI10: 0.0053444046 | BJ10: 0.0051387282 | BM10: 0.00693 | BN10: 0.006896 | BO10: 0.006631 | BP10: 0.006376 | BQ10: 0.006207 | BR10: 0.006119 | BS10: 0.006031 | BT10: 0.005945 | BU10: 0.005861
C11: NI | D11: ACT_EFF | E11: ADCF-MoTP-Mob-Bike--ELC | F11: ACT | L11: 0.35 | R11: 0.35 | X11: NI | Y11: ACT_EFF | Z11: T_C_CHYBPET | AA11: ACT | AG11: 0.32080058 | AH11: 0.37690024 | AJ11: 0.43089793 | AM11: 0.32080058 | AN11: 0.3701514 | AP11: 0.40522794 | AR11: NI | AS11: COM_PROJ | AV11: ADCF-MoTP-Mob-Bike | BB11: 0.038036799 | BC11: 0.036225466 | BD11: 0.034199205 | BE11: 0.03217555 | BF11: 0.030167747 | BG11: 0.028285233 | BH11: 0.026520191 | BI11: 0.02486529 | BJ11: 0.023313658 | BM11: 0.038555 | BN11: 0.037984 | BO11: 0.036068 | BP11: 0.034249 | BQ11: 0.032928 | BR11: 0.032054 | BS11: 0.031203 | BT11: 0.030374 | BU11: 0.029568
C12: NI | D12: ACT_EFF | E12: ADCF-MoTP-Mob-Bike--PET | F12: ACT | L12: 0.1 | R12: 0.1 | X12: NI | Y12: ACT_EFF | Z12: T_C_CICEDSL | AA12: ACT | AG12: 0.24232913 | AH12: 0.26016473 | AJ12: 0.30361985 | AM12: 0.24232913 | AN12: 0.26005135 | AP12: 0.28945347 | AR12: NI | AS12: COM_PROJ | AV12: ADCF-MoTP-Mob-MTr | BB12: 0.066350686 | BC12: 0.063191031 | BD12: 0.059656458 | BE12: 0.056126432 | BF12: 0.052624057 | BG12: 0.049340235 | BH12: 0.046261328 | BI12: 0.04337455 | BJ12: 0.040667912 | BM12: 0.067255 | BN12: 0.066259 | BO12: 0.062917 | BP12: 0.059743 | BQ12: 0.057439 | BR12: 0.055914 | BS12: 0.05443 | BT12: 0.052985 | BU12: 0.051578
C13: NI | D13: ACT_EFF | E13: ADCF-MoTP-Mob-MTr--DSL | F13: ACT | L13: 0.13 | R13: 0.13 | X13: NI | Y13: ACT_EFF | Z13: T_C_CICEPET | AA13: ACT | AG13: 0.2244655 | AH13: 0.25997066 | AJ13: 0.32502287 | AM13: 0.2244655 | AN13: 0.26049145 | AP13: 0.31975215 | AR13: NI | AS13: COM_PROJ | AV13: ADCF-MoTP-Mob-Trac | BB13: 0.20615555 | BC13: 0.19633831 | BD13: 0.18535619 | BE13: 0.17438818 | BF13: 0.16350609 | BG13: 0.15330306 | BH13: 0.14373672 | BI13: 0.13476732 | BJ13: 0.12635764 | BM13: 0.208966 | BN13: 0.205871 | BO13: 0.195486 | BP13: 0.185624 | BQ13: 0.178467 | BR13: 0.173729 | BS13: 0.169116 | BT13: 0.164626 | BU13: 0.160255
C14: NI | D14: ACT_EFF | E14: ADCF-MoTP-Mob-MTr--ELC | F14: ACT | L14: 0.44 | R14: 0.44 | X14: NI | Y14: ACT_EFF | Z14: T_C_CPHEVDSL | AA14: TRADSL | AG14: 0.24232913 | AH14: 0.26016473 | AJ14: 0.30361985 | AM14: 0.24232913 | AN14: 0.26005135 | AP14: 0.28945347 | AR14: NI | AS14: COM_PROJ | AV14: ADCF-MoTP-Mob-Uti | BB14: 0.060963141 | BC14: 0.058060044 | BD14: 0.054812472 | BE14: 0.051569077 | BF14: 0.048351088 | BG14: 0.045333905 | BH14: 0.042505 | BI14: 0.039852623 | BJ14: 0.037365758 | BM14: 0.061794 | BN14: 0.060879 | BO14: 0.057808 | BP14: 0.054892 | BQ14: 0.052775 | BR14: 0.051374 | BS14: 0.05001 | BT14: 0.048682 | BU14: 0.04739
C15: NI | D15: ACT_EFF | E15: ADCF-MoTP-Mob-MTr--H2R | F15: ACT | L15: 0.27 | R15: 0.27 | X15: NI | Y15: ACT_EFF | Z15: T_C_CPHEVDSL | AA15: TRAELC | AG15: 1.3286636 | AH15: 1.1547045 | AJ15: 1.2533056 | AM15: 1.3286636 | AN15: 1.152396 | AP15: 1.2522726 | AR15: NI | AS15: COM_PROJ | AV15: ADCF-MoTP-Stat | BB15: 0.59296052 | BC15: 0.57621869 | BD15: 0.5578646 | BE15: 0.53824277 | BF15: 0.5175288 | BG15: 0.49761199 | BH15: 0.47846168 | BI15: 0.46004835 | BJ15: 0.44234364 | BM15: 0.596501 | BN15: 0.593595 | BO15: 0.570768 | BP15: 0.548819 | BQ15: 0.53432 | BR15: 0.526701 | BS15: 0.519191 | BT15: 0.511788 | BU15: 0.50449
C16: NI | D16: ACT_EFF | E16: ADCF-MoTP-Mob-Trac--DSL | F16: ACT | L16: 0.11 | R16: 0.11 | X16: NI | Y16: ACT_EFF | Z16: T_C_CPHEVPET | AA16: TRAELC | AG16: 1.3286636 | AH16: 1.1547045 | AJ16: 1.2533056 | AM16: 1.3286636 | AN16: 1.152396 | AP16: 1.2522726 | AR16: NI | AS16: COM_PROJ | AV16: ADCF-PUMP | BB16: 0.52133017 | BC16: 0.50661078 | BD16: 0.49047388 | BE16: 0.47322239 | BF16: 0.4550107 | BG16: 0.43749986 | BH16: 0.42066293 | BI16: 0.40447395 | BJ16: 0.388908 | BM16: 0.524443 | BN16: 0.521888 | BO16: 0.501819 | BP16: 0.482521 | BQ16: 0.469774 | BR16: 0.463075 | BS16: 0.456472 | BT16: 0.449963 | BU16: 0.443547
C17: NI | D17: ACT_EFF | E17: ADCF-MoTP-Mob-Trac--ELC | F17: ACT | L17: 0.39 | R17: 0.39 | X17: NI | Y17: ACT_EFF | Z17: T_C_CPHEVPET | AA17: TRAPET | AG17: 0.2244655 | AH17: 0.25997066 | AJ17: 0.32502287 | AM17: 0.2244655 | AN17: 0.26049145 | AP17: 0.31975215 | AR17: NI | AS17: COM_PROJ | AV17: ADCF-RFGR | BB17: 1.9674706 | BC17: 1.9119204 | BD17: 1.8510207 | BE17: 1.7859145 | BF17: 1.7171846 | BG17: 1.6510997 | BH17: 1.5875581 | BI17: 1.5264618 | BJ17: 1.4677168 | BM17: 1.979219 | BN17: 1.969576 | BO17: 1.893835 | BP17: 1.821006 | BQ17: 1.7729 | BR17: 1.747619 | BS17: 1.7227 | BT17: 1.698135 | BU17: 1.673921
C18: NI | D18: ACT_EFF | E18: ADCF-MoTP-Mob-Trac--H2R | F18: ACT | L18: 0.24 | R18: 0.24 | X18: NI | Y18: ACT_EFF | Z18: T_F_HTrBEVELC | AA18: ACT | AG18: 0.178388 | AM18: 0.178388 | AR18: NI | AS18: COM_PROJ | AV18: ADCF-WH | BB18: 1.2105336 | BC18: 1.1763551 | BD18: 1.138885 | BE18: 1.0988269 | BF18: 1.0565392 | BG18: 1.0158789 | BH18: 0.97678334 | BI18: 0.93919238 | BJ18: 0.90304809 | BM18: 1.217762 | BN18: 1.211829 | BO18: 1.165227 | BP18: 1.120418 | BQ18: 1.090819 | BR18: 1.075265 | BS18: 1.059932 | BT18: 1.044818 | BU18: 1.02992
C19: NI | D19: ACT_EFF | E19: ADCF-MoTP-Mob-Uti--DSL | F19: ACT | L19: 0.23 | R19: 0.23 | X19: NI | Y19: ACT_EFF | Z19: T_F_HTrFCH2R | AA19: ACT | AG19: 0.095545 | AM19: 0.095545 | AR19: NI | AS19: COM_PROJ | AV19: AFISH-BOAT | BB19: 0.14914749 | BC19: 0.14053844 | BD19: 0.13043992 | BE19: 0.12109731 | BF19: 0.11245195 | BG19: 0.1044238 | BH19: 0.096968791 | BI19: 0.090046011 | BJ19: 0.083617461 | BM19: 0.15258 | BN19: 0.148351 | BO19: 0.143156 | BP19: 0.13804 | BQ19: 0.133007 | BR19: 0.128158 | BS19: 0.123485 | BT19: 0.118983 | BU19: 0.114645
C20: NI | D20: ACT_EFF | E20: ADCF-MoTP-Mob-Uti--ELC | F20: ACT | L20: 0.8 | R20: 0.8 | X20: NI | Y20: ACT_EFF | Z20: T_F_HTrICEDSL | AA20: ACT | AG20: 0.0565 | AH20: 0.0565 | AJ20: 0.0565 | AM20: 0.049135097 | AN20: 0.04940497 | AP20: 0.050577567 | AR20: NI | AS20: COM_PROJ | AV20: AFISH-LIG | BB20: 0.00089750349 | BC20: 0.00088056763 | BD20: 0.0008596316 | BE20: 0.00083940311 | BF20: 0.00081985552 | BG20: 0.00080076314 | BH20: 0.00078211537 | BI20: 0.00076390186 | BJ20: 0.0007461125 | BM20: 0.000904 | BN20: 0.000897 | BO20: 0.000888 | BP20: 0.000878 | BQ20: 0.000867 | BR20: 0.000857 | BS20: 0.000847 | BT20: 0.000837 | BU20: 0.000827
C21: NI | D21: ACT_EFF | E21: ADCF-MoTP-Mob-Uti--H2R | F21: ACT | L21: 0.5 | R21: 0.5 | X21: NI | Y21: ACT_EFF | Z21: T_F_MTrBEVELC | AA21: ACT | AG21: 0.19607843 | AM21: 0.19607843 | AR21: NI | AS21: COM_PROJ | AV21: AFISH-RFGR | BB21: 0.073578344 | BC21: 0.072189923 | BD21: 0.070473564 | BE21: 0.06881521 | BF21: 0.067212676 | BG21: 0.065647461 | BH21: 0.064118696 | BI21: 0.062625532 | BJ21: 0.061167141 | BM21: 0.074134 | BN21: 0.073543 | BO21: 0.072773 | BP21: 0.071958 | BQ21: 0.071099 | BR21: 0.070249 | BS21: 0.06941 | BT21: 0.068581 | BU21: 0.067762
C22: NI | D22: ACT_EFF | E22: ADCF-MoTP-Stat-VacP-ELC | F22: ACT | L22: 0.84 | R22: 0.84 | X22: NI | Y22: ACT_EFF | Z22: T_F_MTrFCH2R | AA22: ACT | AG22: 0.12820513 | AM22: 0.12820513 | AR22: NI | AS22: COM_PROJ | AV22: AFORE-LIG | BB22: 0.0059102263 | BC22: 0.0061260108 | BD22: 0.0062618269 | BE22: 0.0064643208 | BF22: 0.0067247354 | BG22: 0.0070303995 | BH22: 0.0073681435 | BI22: 0.0070070311 | BJ22: 0.0066636169 | BM22: 0.006 | BN22: 0.006346 | BO22: 0.006652 | BP22: 0.007042 | BQ22: 0.007513 | BR22: 0.008055 | BS22: 0.008657 | BT22: 0.008443 | BU22: 0.008234
C23: NI | D23: ACT_EFF | E23: ADCF-MoTP-Stat-VPVSD-ELC | F23: ACT | L23: 0.95 | R23: 0.95 | X23: NI | Y23: ACT_EFF | Z23: T_F_MTrICEDSL | AA23: ACT | AG23: 0.13187234 | AH23: 0.13722673 | AJ23: 0.14448842 | AM23: 0.13187234 | AN23: 0.13705712 | AP23: 0.13891373 | AR23: NI | AS23: COM_PROJ | AV23: AFORE-MoTP-Mob-CY | BB23: 0.052075161 | BC23: 0.055075165 | BD23: 0.057732258 | BE23: 0.061119503 | BF23: 0.065203596 | BG23: 0.069906214 | BH23: 0.075133441 | BI23: 0.073273795 | BJ23: 0.071460177 | BM23: 0.052469 | BN23: 0.056051 | BO23: 0.059497 | BP23: 0.063783 | BQ23: 0.068905 | BR23: 0.074807 | BS23: 0.081416 | BT23: 0.080403 | BU23: 0.079403
C24: NI | D24: ACT_EFF | E24: ADCF-PUMP--ELC | F24: ACT | L24: 0.7 | R24: 0.7 | X24: NI | Y24: ACT_EFF | Z24: T_F_VHTBEVELC | AA24: ACT | AG24: 0.163288 | AM24: 0.163288 | AR24: NI | AS24: COM_PROJ | AV24: AFORE-MoTP-Mob-GB | BB24: 0.066202681 | BC24: 0.07001656 | BD24: 0.073394498 | BE24: 0.077700672 | BF24: 0.082892742 | BG24: 0.088871138 | BH24: 0.095516464 | BI24: 0.093152313 | BJ24: 0.090846677 | BM24: 0.066703 | BN24: 0.071257 | BO24: 0.075638 | BP24: 0.081087 | BQ24: 0.087598 | BR24: 0.095101 | BS24: 0.103503 | BT24: 0.102216 | BU24: 0.100944
C25: NI | D25: ACT_EFF | E25: ADCF-RFGR--ELC | F25: ACT | L25: 2.95 | R25: 2.951594 | X25: NI | Y25: ACT_EFF | Z25: T_F_VHTFCH2R | AA25: ACT | AG25: 0.092196 | AM25: 0.092196 | AR25: NI | AS25: COM_PROJ | AV25: AFORE-MoTP-Stat | BB25: 0.15379584 | BC25: 0.16265589 | BD25: 0.1705032 | BE25: 0.18050689 | BF25: 0.19256862 | BG25: 0.20645707 | BH25: 0.22189487 | BI25: 0.21640269 | BJ25: 0.21104646 | BM25: 0.154958 | BN25: 0.165538 | BO25: 0.175716 | BP25: 0.188374 | BQ25: 0.203499 | BR25: 0.22093 | BS25: 0.240448 | BT25: 0.237458 | BU25: 0.234504
C26: NI | D26: ACT_EFF | E26: ADCF-RFGR-HRECSys-ELC | F26: ACT | L26: 3.5 | R26: 3.5 | X26: NI | Y26: ACT_EFF | Z26: T_F_VHTICEDSL | AA26: ACT | AG26: 0.05 | AM26: 0.05 | AR26: NI | AS26: COM_PROJ | AV26: AHORT-IRG | BB26: 0.11250123 | BC26: 0.10711483 | BD26: 0.094161956 | BE26: 0.088344898 | BF26: 0.082900059 | BG26: 0.077802875 | BH26: 0.073030443 | BI26: 0.067715032 | BJ26: 0.062786495 | BM26: 0.115091 | BN26: 0.112956 | BO26: 0.103135 | BP26: 0.100504 | BQ26: 0.097956 | BR26: 0.095486 | BS26: 0.093094 | BT26: 0.089655 | BU26: 0.086343
C27: NI | D27: ACT_EFF | E27: ADCF-WH-Cylinder-ELC | F27: ACT | L27: 0.9 | R27: 0.9 | X27: NI | Y27: ACT_EFF | Z27: T_P_BusBEVELC | AA27: ACT | AG27: 0.26548133 | AH27: 0.30574532 | AJ27: 0.33634751 | AM27: 0.26548133 | AN27: 0.31138463 | AP27: 0.3373593 | AR27: NI | AS27: COM_PROJ | AV27: AHORT-LIG | BB27: 0.0018384769 | BC27: 0.0018226274 | BD27: 0.0016852255 | BE27: 0.0016630231 | BF27: 0.0016413677 | BG27: 0.001620246 | BH27: 0.0015996446 | BI27: 0.0015600514 | BJ27: 0.0015214381 | BM27: 0.001852 | BN27: 0.001855 | BO27: 0.001737 | BP27: 0.001736 | BQ27: 0.001735 | BR27: 0.001734 | BS27: 0.001733 | BT27: 0.001712 | BU27: 0.001691
C28: NI | D28: ACT_EFF | E28: ADCF-WH-Hreco-ELC | F28: ACT | L28: 3.5 | R28: 3.5 | X28: NI | Y28: ACT_EFF | Z28: T_P_BusFCH2R | AA28: ACT | AG28: 0.16129032 | AH28: 0.17574692 | AJ28: 0.20533881 | AM28: 0.16129032 | AN28: 0.17574692 | AP28: 0.20533881 | AR28: NI | AS28: COM_PROJ | AV28: AHORT-MoTP-Mob-MTr | BB28: 0.0065715155 | BC28: 0.0063848942 | BD28: 0.0057567106 | BE28: 0.0055395594 | BF28: 0.0053314263 | BG28: 0.0051319101 | BH28: 0.0049406279 | BI28: 0.004698488 | BJ28: 0.0044682153 | BM28: 0.006672 | BN28: 0.006614 | BO28: 0.006115 | BP28: 0.006035 | BQ28: 0.005956 | BR28: 0.00588 | BS28: 0.005805 | BT28: 0.005661 | BU28: 0.005521
C29: NI | D29: ACT_EFF | E29: AFISH-BOAT-Boat-DSL | F29: ACT | L29: 0.18 | R29: 0.18 | X29: NI | Y29: ACT_EFF | Z29: T_P_BusICEDSL | AA29: ACT | AG29: 0.073200548 | AH29: 0.077679717 | AJ29: 0.082433931 | AM29: 0.073200548 | AN29: 0.077810539 | AP29: 0.080238361 | AR29: NI | AS29: COM_PROJ | AV29: AHORT-MoTP-Mob-Trac | BB29: 0.10500733 | BC29: 0.10202528 | BD29: 0.091987428 | BE29: 0.088517533 | BF29: 0.08519174 | BG29: 0.082003637 | BH29: 0.078947108 | BI29: 0.075077914 | BJ29: 0.071398349 | BM29: 0.106606 | BN29: 0.105687 | BO29: 0.09772 | BP29: 0.096432 | BQ29: 0.095177 | BR29: 0.093952 | BS29: 0.092757 | BT29: 0.090462 | BU29: 0.088223
C30: NI | D30: ACT_EFF | E30: AFISH-BOAT-HYBBOAT-DSL | F30: ACT | L30: 0.19 | R30: 0.193823 | X30: NI | Y30: ACT_EFF | Z30: T_P_CBEVELC | AA30: ACT | AG30: 1.4079926 | AH30: 1.4244365 | AJ30: 1.5685014 | AM30: 1.4079926 | AN30: 1.4026374 | AP30: 1.5730134 | AR30: NI | AS30: COM_PROJ | AV30: AHORT-MoTP-Mob-Uti | BB30: 0.012075843 | BC30: 0.011732907 | BD30: 0.010578554 | BE30: 0.010179516 | BF30: 0.0097970501 | BG30: 0.0094304183 | BH30: 0.0090789174 | BI30: 0.0086339601 | BJ30: 0.0082108102 | BM30: 0.01226 | BN30: 0.012154 | BO30: 0.011238 | BP30: 0.01109 | BQ30: 0.010945 | BR30: 0.010804 | BS30: 0.010667 | BT30: 0.010403 | BU30: 0.010146
C31: NI | D31: ACT_EFF | E31: AFISH-LIG--ELC | F31: ACT | L31: 0.45 | R31: 0.45 | X31: NI | Y31: ACT_EFF | Z31: T_P_CFCH2R | AA31: ACT | AG31: 0.73529412 | AM31: 0.73529412 | AR31: NI | AS31: COM_PROJ | AV31: AHORT-MoTP-Stat | BB31: 0.055334101 | BC31: 0.053762694 | BD31: 0.048473203 | BE31: 0.046644726 | BF31: 0.044892184 | BG31: 0.043212198 | BH31: 0.041601546 | BI31: 0.039562656 | BJ31: 0.037623692 | BM31: 0.056177 | BN31: 0.055692 | BO31: 0.051494 | BP31: 0.050816 | BQ31: 0.050154 | BR31: 0.049508 | BS31: 0.048879 | BT31: 0.047669 | BU31: 0.046489
C32: NI | D32: ACT_EFF | E32: AFISH-RFGR-RF-ELC | F32: ACT | L32: 2.95 | R32: 2.951594 | X32: NI | Y32: ACT_EFF | Z32: T_P_CHYBDSL | AA32: ACT | AG32: 0.3754918 | AH32: 0.42744336 | AJ32: 0.53509347 | AM32: 0.3754918 | AN32: 0.43013781 | AP32: 0.49287454 | AR32: NI | AS32: COM_PROJ | AV32: AINDC-LIG | BB32: 0.0019399217 | BC32: 0.0019505429 | BD32: 0.0019410261 | BE32: 0.0019629873 | BF32: 0.0019758451 | BG32: 0.0019802057 | BH32: 0.0019766466 | BI32: 0.0019665096 | BJ32: 0.0019525754 | BM32: 0.00197 | BN32: 0.002078 | BO32: 0.002175 | BP32: 0.002221 | BQ32: 0.002218 | BR32: 0.002207 | BS32: 0.00219 | BT32: 0.002166 | BU32: 0.002139
C33: NI | D33: ACT_EFF | E33: AFORE-LIG--ELC | F33: ACT | L33: 0.45 | R33: 0.45 | X33: NI | Y33: ACT_EFF | Z33: T_P_CHYBPET | AA33: ACT | AG33: 0.40973966 | AH33: 0.47640356 | AJ33: 0.59501402 | AM33: 0.40973966 | AN33: 0.47187399 | AP33: 0.54536334 | AR33: NI | AS33: COM_PROJ | AV33: AINDC-SH | BB33: 2.2191879 | BC33: 2.186824 | BD33: 2.1220239 | BE33: 2.0926517 | BF33: 2.0539645 | BG33: 2.0072936 | BH33: 1.9538454 | BI33: 1.8954739 | BJ33: 1.8352284 | BM33: 2.270397 | BN33: 2.371286 | BO33: 2.450979 | BP33: 2.471615 | BQ33: 2.437398 | BR33: 2.395627 | BS33: 2.34689 | BT33: 2.292663 | BU33: 2.236096
C34: NI | D34: ACT_EFF | E34: AFORE-MoTP-Mob-CY--DSL | F34: ACT | L34: 0.11 | R34: 0.111111 | X34: NI | Y34: ACT_EFF | Z34: T_P_CICEDSL | AA34: ACT | AG34: 0.27102281 | AH34: 0.29744977 | AJ34: 0.35497794 | AM34: 0.27102281 | AN34: 0.29880791 | AP34: 0.35338723 | AR34: NI | AS34: COM_PROJ | AV34: ALIVE-IRG | BB34: 0.041656915 | BC34: 0.039991708 | BD34: 0.035922437 | BE34: 0.032267227 | BF34: 0.02857589 | BG34: 0.024949548 | BH34: 0.021783396 | BI34: 0.019019036 | BJ34: 0.016605479 | BM34: 0.042616 | BN34: 0.042173 | BO34: 0.037167 | BP34: 0.032756 | BQ34: 0.03013 | BR34: 0.028916 | BS34: 0.02775 | BT34: 0.026631 | BU34: 0.025558
C35: NI | D35: ACT_EFF | E35: AFORE-MoTP-Mob-CY--ELC | F35: ACT | L35: 0.39 | R35: 0.386473 | X35: NI | Y35: ACT_EFF | Z35: T_P_CICEPET | AA35: ACT | AG35: 0.29574227 | AH35: 0.33152026 | AJ35: 0.39472888 | AM35: 0.29574227 | AN35: 0.32780117 | AP35: 0.3910213 | AR35: NI | AS35: COM_PROJ | AV35: ALIVE-LIG | BB35: 0.02432121 | BC35: 0.024311705 | BD35: 0.022969182 | BE35: 0.021700794 | BF35: 0.020213802 | BG35: 0.018562871 | BH35: 0.017046778 | BI35: 0.01565451 | BJ35: 0.014375953 | BM35: 0.024505 | BN35: 0.024743 | BO35: 0.022361 | BP35: 0.020208 | BQ35: 0.019061 | BR35: 0.018758 | BS35: 0.01846 | BT35: 0.018167 | BU35: 0.017878
C36: NI | D36: ACT_EFF | E36: AFORE-MoTP-Mob-CY--H2R | F36: ACT | L36: 0.24 | R36: 0.241546 | X36: NI | Y36: ACT_EFF | Z36: T_P_CPHEVDSL | AA36: TRADSL | AG36: 0.27102281 | AH36: 0.29744977 | AJ36: 0.35497794 | AM36: 0.27102281 | AN36: 0.29880791 | AP36: 0.35338723 | AR36: NI | AS36: COM_PROJ | AV36: ALIVE-MoTP-Mob-Bike | BB36: 0.015780547 | BC36: 0.015459689 | BD36: 0.01424267 | BE36: 0.013121458 | BF36: 0.01191832 | BG36: 0.010672662 | BH36: 0.0095571959 | BI36: 0.0085583139 | BJ36: 0.0076638314 | BM36: 0.016021 | BN36: 0.016015 | BO36: 0.014293 | BP36: 0.012756 | BQ36: 0.011882 | BR36: 0.011547 | BS36: 0.011222 | BT36: 0.010906 | BU36: 0.010599
C37: NI | D37: ACT_EFF | E37: AFORE-MoTP-Mob-GB--DSL | F37: ACT | L37: 0.11 | R37: 0.111111 | X37: NI | Y37: ACT_EFF | Z37: T_P_CPHEVDSL | AA37: TRAELC | AG37: 1.4079926 | AH37: 1.4244365 | AJ37: 1.5685014 | AM37: 1.4079926 | AN37: 1.4026374 | AP37: 1.5730134 | AR37: NI | AS37: COM_PROJ | AV37: ALIVE-MoTP-Mob-MTr | BB37: 0.0053619301 | BC37: 0.0052529087 | BD37: 0.0048393888 | BE37: 0.0044584221 | BF37: 0.0040496187 | BG37: 0.0036263679 | BH37: 0.0032473537 | BI37: 0.0029079525 | BJ37: 0.0026040244 | BM37: 0.005444 | BN37: 0.005441 | BO37: 0.004856 | BP37: 0.004334 | BQ37: 0.004037 | BR37: 0.003923 | BS37: 0.003813 | BT37: 0.003706 | BU37: 0.003601
C38: NI | D38: ACT_EFF | E38: AFORE-MoTP-Mob-GB--ELC | F38: ACT | L38: 0.39 | R38: 0.386473 | X38: NI | Y38: ACT_EFF | Z38: T_P_CPHEVPET | AA38: TRAELC | AG38: 1.408 | AH38: 1.424 | AJ38: 1.569 | AM38: 1.4079926 | AN38: 1.4026374 | AP38: 1.5730134 | AR38: NI | AS38: COM_PROJ | AV38: ALIVE-MoTP-Mob-Trac | BB38: 0.085679165 | BC38: 0.083937094 | BD38: 0.077329392 | BE38: 0.071241862 | BF38: 0.064709525 | BG38: 0.057946331 | BH38: 0.05189 | BI38: 0.046466653 | BJ38: 0.041610135 | BM38: 0.086984 | BN38: 0.08695 | BO38: 0.0776 | BP38: 0.069256 | BQ38: 0.06451 | BR38: 0.062693 | BS38: 0.060928 | BT38: 0.059212 | BU38: 0.057544
C39: NI | D39: ACT_EFF | E39: AFORE-MoTP-Mob-GB--H2R | F39: ACT | L39: 0.24 | R39: 0.241546 | X39: NI | Y39: ACT_EFF | Z39: T_P_CPHEVPET | AA39: TRAPET | AG39: 0.296 | AH39: 0.332 | AJ39: 0.395 | AM39: 0.29574227 | AN39: 0.32780117 | AP39: 0.3910213 | AR39: NI | AS39: COM_PROJ | AV39: ALIVE-MoTP-Mob-Uti | BB39: 0.009853104 | BC39: 0.0096527658 | BD39: 0.0088928801 | BE39: 0.0081928141 | BF39: 0.0074415954 | BG39: 0.006663828 | BH39: 0.0059673499 | BI39: 0.0053436651 | BJ39: 0.0047851655 | BM39: 0.010003 | BN39: 0.009999 | BO39: 0.008924 | BP39: 0.007964 | BQ39: 0.007419 | BR39: 0.00721 | BS39: 0.007007 | BT39: 0.006809 | BU39: 0.006618
C40: NI | D40: ACT_EFF | E40: AFORE-MoTP-Stat--ELC | F40: ACT | L40: 0.9 | R40: 0.9 | X40: NI | Y40: ACT_EFF | Z40: T_P_McyBEVELC | AA40: ACT | AG40: 5.7874235 | AH40: 4.9403706 | AJ40: 4.728734 | AM40: 5.7874235 | AN40: 4.9866436 | AP40: 4.7639962 | AR40: NI | AS40: COM_PROJ | AV40: ALU-PH-FURN | BB40: 0 | BC40: 0 | BD40: 0 | BE40: 0 | BF40: 0 | BG40: 0 | BH40: 0 | BI40: 0 | BJ40: 0 | BM40: 0 | BN40: 0 | BO40: 0 | BP40: 0 | BQ40: 0 | BR40: 0 | BS40: 0 | BT40: 0 | BU40: 0
C41: NI | D41: ACT_EFF | E41: AHORT-IRG-Irg-ELC | F41: ACT | L41: 0.7 | R41: 0.7 | X41: NI | Y41: ACT_EFF | Z41: T_P_McyICEPET | AA41: ACT | AG41: 0.58602989 | AH41: 0.61568558 | AJ41: 0.71916678 | AM41: 0.58602989 | AN41: 0.61275425 | AP41: 0.67120833 | AR41: NI | AS41: COM_PROJ | AV41: AOTH-ELC | BB41: 0.011299596 | BC41: 0.010854347 | BD41: 0.010322376 | BE41: 0.0098164764 | BF41: 0.0093353714 | BG41: 0.0088778453 | BH41: 0.0084427426 | BI41: 0.0080289642 | BJ41: 0.007635465 | BM41: 0.011472 | BN41: 0.011244 | BO41: 0.010966 | BP41: 0.010694 | BQ41: 0.01043 | BR41: 0.010171 | BS41: 0.00992 | BT41: 0.009674 | BU41: 0.009435
...

Sheet car demand
A1: Sum of val_field | D1: year | E1: 0.8 | F1: 0.9 | G1: =F1 -> 0.9 | H1: =G1 -> 0.9 | I1: =H1 -> 0.9 | J1: =I1 -> 0.9 | K1: =J1 -> 0.9 | L1: =K1 -> 0.9 | M1: =L1 -> 0.9
A2: region | B2: commodity | C2: scenario | D2: 2018 | E2: 2020 | F2: 2025 | G2: 2030 | H2: 2035 | I2: 2040 | J2: 2045 | K2: 2050 | L2: 2055 | M2: 2060
A3: NI | B3: T_C_Car | C3: BASE | D3: 6.36
A4: NI | B4: T_C_Car | C4: NZL_0001 | E4: 6.36 | F4: 7.08 | G4: 7.94 | H4: 9.18 | I4: 10.45 | J4: 11.56 | K4: 12.85 | L4: 14.25 | M4: 15.58
A5: NI | B5: T_C_Car | C5: NZL_0002 | E5: 6.74 | F5: 7.03 | G5: 7.45 | H5: 7.89 | I5: 8.43 | J5: 9.01 | K5: 9.66 | L5: 10.58 | M5: 11.51
A6: NI | B6: T_P_Car | C6: BASE | D6: 26.71 | P6: region | Q6: commodity | R6: scenario | S6: 2018 | T6: 2020 | U6: 2025 | V6: 2030 | W6: 2035 | X6: 2040 | Y6: 2045 | Z6: 2050 | AA6: 2055 | AB6: 2060
A7: NI | B7: T_P_Car | C7: NZL_0001 | E7: 26.71 | F7: 28.37 | G7: 30.96 | H7: 34.55 | I7: 37.83 | J7: 40.08 | K7: 42.65 | L7: 45.41 | M7: 47.82 | P7: NI | Q7: T_O_JET_Int | R7: BASE | S7: 45.716103
A8: NI | B8: T_P_Car | C8: NZL_0002 | E8: 26.42 | F8: 26.64 | G8: 27.36 | H8: 28.07 | I8: 29.04 | J8: 29.98 | K8: 31.13 | L8: 33.11 | M8: 35.08 | P8: NI | Q8: T_O_JET_Int | R8: NZL_0001 | T8: 45.716103 | U8: 49.349502 | V8: 55.560463 | W8: 64.451116 | X8: 73.991378 | Y8: 84.892824 | Z8: 95.14056 | AA8: 102.7165 | AB8: 110.8957
A9: SI | B9: T_C_Car | C9: BASE | D9: 2.65 | P9: NI | Q9: T_O_JET_Int | R9: NZL_0002 | T9: 48.744455 | U9: 53.518676 | V9: 59.407196 | W9: 65.04728 | X9: 69.800488 | Y9: 70.886291 | Z9: 67.656479 | AA9: 64.046806 | AB9: 60.629719
A10: SI | B10: T_C_Car | C10: NZL_0001 | E10: 2.65 | F10: 2.95 | G10: 3.31 | H10: 3.83 | I10: 4.36 | J10: 4.82 | K10: 5.36 | L10: 5.94 | M10: 6.49 | P10: SI | Q10: T_O_JET_Int | R10: BASE | S10: 11.429026
A11: SI | B11: T_C_Car | C11: NZL_0002 | E11: 2.81 | F11: 2.93 | G11: 3.11 | H11: 3.29 | I11: 3.52 | J11: 3.75 | K11: 4.03 | L11: 4.41 | M11: 4.8 | P11: SI | Q11: T_O_JET_Int | R11: NZL_0001 | T11: 11.429026 | U11: 12.296696 | V11: 13.775821 | W11: 15.884485 | X11: 18.165421 | Y11: 20.793191 | Z11: 23.265394 | AA11: 25.086356 | AB11: 27.049843
A12: SI | B12: T_P_Car | C12: BASE | D12: 9.32 | P12: SI | Q12: T_O_JET_Int | R12: NZL_0002 | T12: 12.159827 | U12: 13.295971 | V12: 14.668574 | W12: 15.989388 | X12: 17.106946 | Y12: 17.337362 | Z12: 16.525932 | AA12: 15.623915 | AB12: 14.771132
A13: SI | B13: T_P_Car | C13: NZL_0001 | E13: 9.32 | F13: 9.9 | G13: 10.8 | H13: 12.05 | I13: 13.2 | J13: 13.98 | K13: 14.88 | L13: 15.84 | M13: 16.68
A14: SI | B14: T_P_Car | C14: NZL_0002 | E14: 9.22 | F14: 9.29 | G14: 9.55 | H14: 9.79 | I14: 10.13 | J14: 10.46 | K14: 10.86 | L14: 11.55 | M14: 12.24
A16: NI | B16: T_O_JET_Int | C16: BASE | D16: 45.716103
A17: NI | B17: T_O_JET_Int | C17: NZL_0001 | E17: 45.716103 | F17: 49.349502 | G17: 55.560463 | H17: 64.451116 | I17: 73.991378 | J17: 84.892824 | K17: 95.14056 | L17: 102.7165 | M17: 110.8957
A18: NI | B18: T_O_JET_Int | C18: NZL_0002 | E18: 48.744455 | F18: 53.518676 | G18: 59.407196 | H18: 65.04728 | I18: 69.800488 | J18: 70.886291 | K18: 67.656479 | L18: 64.046806 | M18: 60.629719
A19: SI | B19: T_O_JET_Int | C19: BASE | D19: 11.429026
A20: SI | B20: T_O_JET_Int | C20: NZL_0001 | E20: 11.429026 | F20: 12.296696 | G20: 13.775821 | H20: 15.884485 | I20: 18.165421 | J20: 20.793191 | K20: 23.265394 | L20: 25.086356 | M20: 27.049843
A21: SI | B21: T_O_JET_Int | C21: NZL_0002 | E21: 12.159827 | F21: 13.295971 | G21: 14.668574 | H21: 15.989388 | I21: 17.106946 | J21: 17.337362 | K21: 16.525932 | L21: 15.623915 | M21: 14.771132
E23: =E17+E20 -> 57.145129 | F23: =F17+F20 -> 61.646198 | G23: =G17+G20 -> 69.336284 | H23: =H17+H20 -> 80.335601 | I23: =I17+I20 -> 92.156799 | J23: =J17+J20 -> 105.68602 | K23: =K17+K20 -> 118.40595 | L23: =L17+L20 -> 127.80285 | M23: =M17+M20 -> 137.94554
A25: ~TFM_INS-TS | P25: =VLOOKUP('kea-tui'!A1,'kea-tui'!$E$1:$F$4,2,FALSE) -> kea
A26: region | B26: commodity | C26: attribute | D26: limtype | E26: 2020 | F26: 2025 | G26: 2030 | H26: 2035 | I26: 2040 | J26: 2045 | K26: 2050 | L26: 2055 | M26: 2060
A27: NI | B27: T_C_Car | C27: =IF(P27=$P$25,"demand","\I:") -> \I: | D27: =IF(E27=0,"\I:","") -> \I: | P27: BASE
A28: NI | B28: T_C_Car | C28: =IF(P28=$P$25,"demand","\I:") -> \I: | D28: =IF(E28=0,"\I:","") | E28: =E4*E$1 -> 5.088 | F28: =F4 -> 7.08 | G28: =G4 -> 7.94 | H28: =H4 -> 9.18 | I28: =I4 -> 10.45 | J28: =J4 -> 11.56 | K28: =K4 -> 12.85 | L28: =L4 -> 14.25 | M28: =M4 -> 15.58 | P28: tui
A29: NI | B29: T_C_Car | C29: =IF(P29=$P$25,"demand","\I:") -> demand | D29: =IF(E29=0,"\I:","") | E29: =E5*E$1 -> 5.392 | F29: =F5 -> 7.03 | G29: =G5 -> 7.45 | H29: =H5 -> 7.89 | I29: =I5 -> 8.43 | J29: =J5 -> 9.01 | K29: =K5 -> 9.66 | L29: =L5 -> 10.58 | M29: =M5 -> 11.51 | P29: kea
A30: NI | B30: T_P_Car | C30: =IF(P30=$P$25,"demand","\I:") -> \I: | D30: =IF(E30=0,"\I:","") -> \I: | P30: =P27 -> BASE
A31: NI | B31: T_P_Car | C31: =IF(P31=$P$25,"demand","\I:") -> \I: | D31: =IF(E31=0,"\I:","") | E31: =E7*E$1 -> 21.368 | F31: =F7*F$1 -> 25.533 | G31: =G7*G$1 -> 27.864 | H31: =H7*H$1 -> 31.095 | I31: =I7*I$1 -> 34.047 | J31: =J7*J$1 -> 36.072 | K31: =K7*K$1 -> 38.385 | L31: =L7*L$1 -> 40.869 | M31: =M7*M$1 -> 43.038 | P31: =P28 -> tui
A32: NI | B32: T_P_Car | C32: =IF(P32=$P$25,"demand","\I:") -> demand | D32: =IF(E32=0,"\I:","") | E32: =E8*E$1 -> 21.136 | F32: =F8*F$1 -> 23.976 | G32: =G8*G$1 -> 24.624 | H32: =H8*H$1 -> 25.263 | I32: =I8*I$1 -> 26.136 | J32: =J8*J$1 -> 26.982 | K32: =K8*K$1 -> 28.017 | L32: =L8*L$1 -> 29.799 | M32: =M8*M$1 -> 31.572 | P32: =P29 -> kea
A33: SI | B33: T_C_Car | C33: =IF(P33=$P$25,"demand","\I:") -> \I: | D33: =IF(E33=0,"\I:","") -> \I: | P33: =P30 -> BASE
A34: SI | B34: T_C_Car | C34: =IF(P34=$P$25,"demand","\I:") -> \I: | D34: =IF(E34=0,"\I:","") | E34: =E10*E$1 -> 2.12 | F34: =F10 -> 2.95 | G34: =G10 -> 3.31 | H34: =H10 -> 3.83 | I34: =I10 -> 4.36 | J34: =J10 -> 4.82 | K34: =K10 -> 5.36 | L34: =L10 -> 5.94 | M34: =M10 -> 6.49 | P34: =P31 -> tui
A35: SI | B35: T_C_Car | C35: =IF(P35=$P$25,"demand","\I:") -> demand | D35: =IF(E35=0,"\I:","") | E35: =E11*E$1 -> 2.248 | F35: =F11 -> 2.93 | G35: =G11 -> 3.11 | H35: =H11 -> 3.29 | I35: =I11 -> 3.52 | J35: =J11 -> 3.75 | K35: =K11 -> 4.03 | L35: =L11 -> 4.41 | M35: =M11 -> 4.8 | P35: =P32 -> kea
A36: SI | B36: T_P_Car | C36: =IF(P36=$P$25,"demand","\I:") -> \I: | D36: =IF(E36=0,"\I:","") -> \I: | P36: =P33 -> BASE
A37: SI | B37: T_P_Car | C37: =IF(P37=$P$25,"demand","\I:") -> \I: | D37: =IF(E37=0,"\I:","") | E37: =E13*E$1 -> 7.456 | F37: =F13*F$1 -> 8.91 | G37: =G13*G$1 -> 9.72 | H37: =H13*H$1 -> 10.845 | I37: =I13*I$1 -> 11.88 | J37: =J13*J$1 -> 12.582 | K37: =K13*K$1 -> 13.392 | L37: =L13*L$1 -> 14.256 | M37: =M13*M$1 -> 15.012 | P37: =P34 -> tui
A38: SI | B38: T_P_Car | C38: =IF(P38=$P$25,"demand","\I:") -> demand | D38: =IF(E38=0,"\I:","") | E38: =E14*E$1 -> 7.376 | F38: =F14*F$1 -> 8.361 | G38: =G14*G$1 -> 8.595 | H38: =H14*H$1 -> 8.811 | I38: =I14*I$1 -> 9.117 | J38: =J14*J$1 -> 9.414 | K38: =K14*K$1 -> 9.774 | L38: =L14*L$1 -> 10.395 | M38: =M14*M$1 -> 11.016 | P38: =P35 -> kea
C39: *
A40: =A16 -> NI | B40: =B16 -> T_O_JET_Int | C40: =IF(P40=$P$25,"demand","\I:") -> \I: | D40: =IF(E40=0,"\I:","") -> \I: | P40: BASE
A41: =A17 -> NI | B41: =B17 -> T_O_JET_Int | C41: =IF(P41=$P$25,"demand","\I:") -> \I: | D41: =IF(E41=0,"\I:","") | E41: =E17*E$1^2 -> 29.258306 | F41: =F17*F$1^2 -> 39.973097 | G41: =G17*G$1^2 -> 45.003975 | H41: =H17*H$1^2 -> 52.205404 | I41: =I17*I$1^2 -> 59.933016 | J41: =J17*J$1^2 -> 68.763188 | K41: =K17*K$1^2 -> 77.063854 | L41: =L17*L$1^2 -> 83.200363 | M41: =M17*M$1^2 -> 89.825516 | P41: tui
A42: =A18 -> NI | B42: =B18 -> T_O_JET_Int | C42: =IF(P42=$P$25,"demand","\I:") -> demand | D42: =IF(E42=0,"\I:","") | E42: =E41 -> 29.258306 | F42: =F41 -> 39.973097 | G42: =G41 -> 45.003975 | H42: =H41 -> 52.205404 | I42: =I18*I$1^2 -> 56.538396 | J42: =J18*J$1^2 -> 57.417896 | K42: =K18*K$1^2 -> 54.801748 | L42: =L18*L$1^2 -> 51.877913 | M42: =M18*M$1^2 -> 49.110072 | P42: kea
A43: =A19 -> SI | B43: =B19 -> T_O_JET_Int | C43: =IF(P43=$P$25,"demand","\I:") -> \I: | D43: =IF(E43=0,"\I:","") -> \I: | P43: =P40 -> BASE
...

Sheet transport
A1: =Veda!$E$5 -> nz | E1: ~UC_Sets: R_S: AllRegions
Q2: Source: EV uptake report
Q3: Table 36 EV Import Limit Assumptions for LPVs | W3: LPV+LCV
F4: ~UC_T: UC_NCAP | R4: BEVs | T4: PHEVs | W4: 240000
D5: UC_N | E5: Pset_PN | F5: LimType | G5: =H5-5 -> 2017 | H5: =VLOOKUP($A$1,$R$18:$S$22,2,FALSE) -> 2022 | I5: =H5+5 -> 2027 | J5: =I5+5 -> 2032 | K5: =J5+3 -> 2035 | L5: UC_RHST | M5: UC_RHST~0 | N5: UC_Desc | R5: Limit | S5: % of LPV imports | T5: Limit | U5: % of LPV imports
D6: MAX_BEV_UPTAKE | E6: T_P_C*BEV*,T_P_C*H2R* | F6: LO | G6: =+G7-1 -> -0.942 | H6: =+H7-1 -> -0.812 | I6: =+I7-1 -> -0.45 | J6: =+J7-1 -> -0.13 | K6: =+K7-1 -> 0 | L6: 0 | M6: 5 | N6: Max number of BEV cars per year | Q6: 2020 | R6: =+$V$6*S6 -> 0 | S6: 0.03 | T6: =+$V$6*U6 -> 0 | U6: 0.01
E7: T_P_C*,-T_P_C*BEV*,-T_P_C*H2R* | G7: 0.058 | H7: 0.188 | I7: 0.55 | J7: 0.87 | K7: 1 | Q7: 2025 | R7: =+$V$6*S7 -> 0 | S7: 0.03 | T7: =+$V$6*U7 -> 0 | U7: 0.01
Q8: 2030 | R8: =+$V$6*S8 -> 0 | S8: 0.11 | T8: =+$V$6*U8 -> 0 | U8: 0.02
Q9: 2035 | R9: =+$V$6*S9 -> 0 | S9: 0.42 | T9: =+$V$6*U9 -> 0 | U9: 0.04
F10: ~UC_T: UC_NCAP | Q10: 2040 | R10: =+$V$6*S10 -> 0 | S10: 0.65 | T10: =+$V$6*U10 -> 0 | U10: 0.07 | W10: 0.99999
D11: UC_N | E11: Pset_PN | F11: LimType | G11: =H11-5 -> 2017 | H11: =$H$5 -> 2022 | I11: =H11+5 -> 2027 | J11: =I11+5 -> 2032 | K11: =J11+20 -> 2052 | L11: UC_RHST | M11: UC_RHST~0 | N11: UC_Desc | Q11: 2045 | R11: =+$V$6*S11 -> 0 | S11: 0.9 | T11: =+$V$6*U11 -> 0 | U11: 0.11 | W11: 1
D12: MAX_PHEV_UPTAKE | E12: T_P_C*PHEV* | F12: LO | G12: =+G13-1 -> -0.99 | H12: =+H13-1 -> -0.909 | I12: =+I13-1 -> -0.74 | J12: =+J13-1 -> -0.3 | K12: =+K13-1 -> 0 | L12: 0 | M12: 5 | N12: Max number of PHEV cars per year | Q12: 2050 | R12: =+$V$6*S12 -> 0 | S12: 1 | T12: =+$V$6*U12 -> 0 | U12: 0.15 | W12: 1
E13: T_P_C*,-T_P_C*PHEV* | G13: 0.01 | H13: 0.091 | I13: 0.26 | J13: 0.7 | K13: 1 | Q13: 2055 | R13: =+$V$6*S13 -> 0 | S13: 1 | T13: =+$V$6*U13 -> 0 | U13: 0.17 | W13: 1
F16: ~UC_T: UC_NCAP
D17: UC_N | E17: Pset_PN | F17: LimType | G17: * | H17: =$H$5 -> 2022 | I17: =H17+5 -> 2027 | J17: =I17+5 -> 2032 | K17: =J17+5 -> 2037 | L17: UC_RHST | M17: UC_RHST~0 | N17: UC_Desc
D18: MAX_BEV_UPTAKE_commercial | E18: T_C_C*BEV*,T_C_C*H2R* | F18: LO | H18: -0.97 | I18: -0.89 | J18: -0.58 | K18: -1e-05 | L18: 0 | M18: 5 | N18: Max number of BEV commercial cars per year | R18: bas | S18: 2030
E19: T_C_C*,-T_C_C*BEV*,-T_c_C*H2R* | H19: 0.03 | I19: 0.11 | J19: 0.42 | K19: 0.99999 | R19: tui | S19: 2029
R20: kea | S20: 2028
R21: nz | S21: 2022
F22: ~UC_T: UC_NCAP
D23: UC_N | E23: Pset_PN | F23: LimType | G23: * | H23: =$H$5 -> 2022 | I23: =H23+5 -> 2027 | J23: =I23+5 -> 2032 | K23: =J23+20 -> 2052 | L23: UC_RHST | M23: UC_RHST~0 | N23: UC_Desc
D24: MAX_PHEV_UPTAKE_commercial | E24: T_C_C*PHEV* | F24: LO | H24: -0.99 | I24: -0.98 | J24: -0.96 | K24: -0.83 | L24: 0 | M24: 5 | N24: Max number of PHEV commerical cars per year
E25: T_C_C*,-T_C_C*PHEV* | H25: 0.01 | I25: 0.02 | J25: 0.04 | K25: 0.17
F28: ~UC_T: UC_NCAP
D29: UC_N | E29: Pset_PN | F29: LimType | G29: * | H29: =$H$5 -> 2022 | I29: =H29+5 -> 2027 | J29: =I29+5 -> 2032 | K29: =J29+5 -> 2037 | L29: =K29+5 -> 2042 | M29: UC_RHST | N29: UC_RHST~0 | O29: UC_Desc
D30: MAX_VHTBEV_UPTAKE | E30: T_F_V*BEV*,T_F_V*H2R* | F30: LO | H30: -0.97 | I30: -0.89 | J30: =I30+0.2 -> -0.69 | K30: =J30+0.2 -> -0.49 | L30: =K30+0.2 -> -0.29 | M30: 0 | N30: 5 | O30: Max number of BEV very heavy trucks
E31: T_F_V*,-T_F_V*BEV*,-T_F_V*H2R* | H31: 0.03 | I31: 0.11 | J31: =1+J30 -> 0.31 | K31: =1+K30 -> 0.51 | L31: =1+L30 -> 0.71
F34: ~UC_T: UC_NCAP
D35: UC_N | E35: Pset_PN | F35: LimType | G35: * | H35: =$H$5 -> 2022 | I35: =H35+5 -> 2027 | J35: =I35+5 -> 2032 | K35: =J35+5 -> 2037 | L35: =K35+5 -> 2042 | M35: UC_RHST | N35: UC_RHST~0 | O35: UC_Desc
D36: MAX_HTBEV_UPTAKE | E36: T_F_H*BEV* | F36: LO | H36: -1 | I36: -0.75 | J36: =I36+0.2 -> -0.55 | K36: =J36+0.2 -> -0.35 | L36: =K36+0.2 -> -0.15 | M36: 0 | N36: 5 | O36: Max number of BEV heavy trucks
E37: T_F_H*,-T_F_H*BEV* | H37: 0 | I37: =1+I36 -> 0.25 | J37: =1+J36 -> 0.45 | K37: =1+K36 -> 0.65 | L37: =1+L36 -> 0.85

Sheet co2 budget
A1: =Veda!$E$5 -> nz | B1: kea | C1: ='kea-tui'!A1 -> kea
B3: ~UC_Sets: R_S: AllRegions
B4: ~UC_Sets: T_S:
G6: =IF(C1=B1,"~UC_T","No CO2 budget") -> ~UC_T
D7: UC_N | E7: commodity | F7: Year | G7: LimType | H7: UC_COMNET | I7: UC_RHSTS | J7: UC_RHSTS~0 | K7: UC_Desc
D8: UC_TOTCO2CAP | E8: co2net | F8: 2025 | G8: UP | H8: 1 | I8: 29443.6 | J8: 5 | K8: CCC Climate Budgets
E9: co2net | F9: 2030 | G9: UP | H9: 1 | I9: 24951.46
E10: co2net | F10: 2035 | G10: UP | H10: 1 | I10: 18884.91
E11: co2net | F11: 2040 | G11: UP | H11: 1 | I11: 12911.14
E12: co2net | F12: 2045 | G12: UP | H12: 1 | I12: 8366.587
E13: co2net | F13: 2050 | G13: UP | H13: 1 | I13: 5276.346
A16: tui | B16: 18.8177 | C16: 24.5 | D16: 30 | E16: 37.92095 | F16: 43.3419 | G16: 48.76285 | H16: 54.1838 | I16: 59.60475 | J16: 65.0257 | K16: 70.4465 | L16: 75.8675 | M16: 81.2885 | N16: 86.7095 | O16: 88.786 | P16: 90.9245 | Q16: 93.127 | R16: 95.396 | S16: 97.7325 | T16: 100.1395 | U16: 102.619 | V16: 105.1725 | W16: 107.8025 | X16: 110.5115 | Y16: 113.302 | Z16: 116.176 | AA16: 119.1365 | AB16: 122.1855 | AC16: 125.326 | AD16: 128.561 | AE16: 131.8925 | AF16: 135.3245 | AG16: 138.859 | AH16: 142.5
B20: 2018 | C20: 2019 | D20: 2020 | E20: 2021 | F20: 2022 | G20: 2023 | H20: 2024 | I20: 2025 | J20: 2026 | K20: 2027 | L20: 2028 | M20: 2029 | N20: 2030 | O20: 2031 | P20: 2032 | Q20: 2033 | R20: 2034 | S20: 2035 | T20: 2036 | U20: 2037 | V20: 2038 | W20: 2039 | X20: 2040 | Y20: 2041 | Z20: 2042 | AA20: 2043 | AB20: 2044 | AC20: 2045 | AD20: 2046 | AE20: 2047 | AF20: 2048 | AG20: 2049 | AH20: 2050 | AJ20: 2025 | AK20: 2050
A21: kea | B21: 18.8177 | C21: 24.5 | D21: 30 | E21: 40.8419 | F21: 51.6838 | G21: 62.5257 | H21: 73.3676 | I21: 84.2095 | J21: 95.0514 | K21: 105.893 | L21: 116.735 | M21: 127.577 | N21: 138.419 | O21: 142.572 | P21: 146.849 | Q21: 151.254 | R21: 155.792 | S21: 160.465 | T21: 165.279 | U21: 170.238 | V21: 175.345 | W21: 180.605 | X21: 186.023 | Y21: 191.604 | Z21: 197.352 | AA21: 203.273 | AB21: 209.371 | AC21: 215.652 | AD21: 222.122 | AE21: 228.785 | AF21: 235.649 | AG21: 242.718 | AH21: 250 | AJ21: 1 | AK21: 4
A22: tui | B22: =AVERAGE(B21,B23) -> 18.8177 | C22: =AVERAGE(C21,C23) -> 24.5 | D22: =AVERAGE(D21,D23) -> 30 | E22: =AVERAGE(E21,E23) -> 37.92095 | F22: =AVERAGE(F21,F23) -> 43.3419 | G22: =AVERAGE(G21,G23) -> 48.76285 | H22: =AVERAGE(H21,H23) -> 54.1838 | I22: {=TREND($E$35:$J$35,$E$34:$J$34,I$20)/0.6} -> 26.666667 | J22: {=TREND($E$35:$J$35,$E$34:$J$34,J$20)/0.6} -> 33.133333 | K22: {=TREND($E$35:$J$35,$E$34:$J$34,K$20)/0.6} -> 39.6 | L22: {=TREND($E$35:$J$35,$E$34:$J$34,L$20)/0.6} -> 46.066667 | M22: {=TREND($E$35:$J$35,$E$34:$J$34,M$20)/0.6} -> 52.533333 | N22: {=TREND($E$35:$J$35,$E$34:$J$34,N$20)/0.6} -> 59 | O22: {=TREND($E$35:$J$35,$E$34:$J$34,O$20)/0.6} -> 65.466667 | P22: {=TREND($E$35:$J$35,$E$34:$J$34,P$20)/0.6} -> 71.933333 | ... AH22: {=TREND($E$35:$J$35,$E$34:$J$34,AH$20)/0.6} -> 188.33333 | AJ22: 1 | AK22: 3.5
A23: bas | B23: 18.8177 | C23: 24.5 | D23: 30 | E23: 35 | F23: 35 | G23: 35 | H23: 35 | I23: 35 | J23: 35 | K23: 35 | L23: 35 | M23: 35 | N23: 35 | O23: 35 | P23: 35 | Q23: 35 | R23: 35 | S23: 35 | T23: 35 | U23: 35 | V23: 35 | W23: 35 | X23: 35 | Y23: 35 | Z23: 35 | AA23: 35 | AB23: 35 | AC23: 35 | AD23: 35 | AE23: 35 | AF23: 35 | AG23: 35 | AH23: 35
A24: nz | B24: =B21 -> 18.8177 | C24: =C21 -> 24.5 | D24: =D21 -> 30 | E24: =E21 -> 40.8419 | F24: =F21 -> 51.6838 | G24: =G21 -> 62.5257 | H24: =H21 -> 73.3676 | I24: {=TREND($E$36:$J$36,$E$34:$J$34,I$20)/0.6} -> 274.20635 | J24: {=TREND($E$36:$J$36,$E$34:$J$34,J$20)/0.6} -> 302.09206 | K24: {=TREND($E$36:$J$36,$E$34:$J$34,K$20)/0.6} -> 329.97778 | L24: {=TREND($E$36:$J$36,$E$34:$J$34,L$20)/0.6} -> 357.86349 | M24: {=TREND($E$36:$J$36,$E$34:$J$34,M$20)/0.6} -> 385.74921 | N24: {=TREND($E$36:$J$36,$E$34:$J$34,N$20)/0.6} -> 413.63492 | O24: {=TREND($E$36:$J$36,$E$34:$J$34,O$20)/0.6} -> 441.52063 | P24: {=TREND($E$36:$J$36,$E$34:$J$34,P$20)/0.6} -> 469.40635 | ... AH24: {=TREND($E$36:$J$36,$E$34:$J$34,AH$20)/0.6} -> 971.34921
A27: ~TFM_INS-TS: attribute=com_taxnet; curr=MioNZDollar
A28: commodity | B28: =B20 -> 2018 | C28: =C20 -> 2019 | D28: =D20 -> 2020 | E28: =E20 -> 2021 | F28: =F20 -> 2022 | G28: =G20 -> 2023 | H28: =H20 -> 2024 | I28: =I20 -> 2025 | ... AH28: =AH20 -> 2050
A29: co2net | B29: =SUMIF($A$21:$A$24,$A$1,B$21:B$24)/1000 -> 0.0188177 | C29: =SUMIF($A$21:$A$24,$A$1,C$21:C$24)/1000 -> 0.0245 | D29: =SUMIF($A$21:$A$24,$A$1,D$21:D$24)/1000 -> 0.03 | E29: =SUMIF($A$21:$A$24,$A$1,E$21:E$24)/1000 -> 0.0408419 | F29: =SUMIF($A$21:$A$24,$A$1,F$21:F$24)/1000 -> 0.0516838 | G29: =SUMIF($A$21:$A$24,$A$1,G$21:G$24)/1000 -> 0.0625257 | H29: =SUMIF($A$21:$A$24,$A$1,H$21:H$24)/1000 -> 0.0733676 | I29: =SUMIF($A$21:$A$24,$A$1,I$21:I$24)/1000 -> 0.27420635 | ... AH29: =SUMIF($A$21:$A$24,$A$1,AH$21:AH$24)/1000 -> 0.97134921
E34: 2025 | F34: 2030 | G34: 2035 | H34: 2040 | I34: 2045 | J34: 2050
E35: 17 | F35: 35 | G35: 52 | H35: 76 | I35: 95 | J35: 112
E36: 175 | F36: 242 | G36: 335 | H36: 407 | I36: 479 | J36: 604

Sheet ev_charging_uc
A10: =IFERROR(Veda!D5,"ts_12t") -> ts_012 | C10: day_night | D10: ts_012 | F10: day_night | G10: ts_048 | I10: day_night | J10: ts_annual | L10: day_night | M10: ts_12t
C11: D | D11: S02aH02,S03aH02,S01aH02,S04aH02 | F11: D | G11: S02aH04,S04aH03,S07aH04,S08aH03,S01aH02,S04aH04,S03aH04,S01aH04,S07aH02,S08aH02,S03aH03,S05aH04,S06aH02,S06aH03,S01aH03,S05aH02,S05aH03,S02aH02,S03aH02,S02aH03,S07aH03,S06aH04,S08aH04,S04aH02 | I11: D | J11: AllSaAllH | L11: D | M11: SaD,WaD,RaP,WaP,FaD,FaP,SaP,RaD
C12: N | D12: S03aH01,S03aH03,S01aH01,S04aH01,S04aH03,S01aH03,S02aH01,S02aH03 | F12: N | G12: S02aH06,S03aH05,S05aH05,S02aH01,S05aH06,S01aH05,S03aH06,S06aH05,S05aH01,S07aH06,S08aH01,S08aH05,S04aH05,S06aH01,S06aH06,S01aH06,S07aH01,S08aH06,S03aH01,S01aH01,S04aH01,S04aH06,S02aH05,S07aH05 | I12: N | J12: AllSaAllH | L12: N | M12: FaP,SaP,FaN,WaP,RaN,RaP,SaN,WaN
I17: 0.75 | K17: share of charging at night
C18: ~UC_Sets: R_E: AllRegions
H21: =IF(H23=H24,"Not Required!","~UC_T: LO") -> ~UC_T: LO
C22: UC_N | D22: Pset_CI | E22: Pset_CO | F22: pset_pn | G22: Cset_CN | H22: TimeSlice | I22: UC_FLO | J22: UC_RHSRT | K22: UC_RHSRT~0
C23: UC_bev night chg limit | D23: TRAELC | F23: *EV* | G23: AuxStoIN | H23: =HLOOKUP($A$10,$D$10:$CU$12,3,FALSE) -> S03aH01,S03aH03,S01aH01,S04aH01,S04aH03,S01aH03,S02aH01,S02aH03 | I23: =1+I24 -> 0.25 | J23: 0 | K23: 3 | M23: night
D24: TRAELC | F24: *EV* | G24: AuxStoIN | H24: =HLOOKUP($A$10,$D$10:$CU$12,2,FALSE) -> S02aH02,S03aH02,S01aH02,S04aH02 | I24: =-$I$17 -> -0.75 | M24: day

Sheet ts_012
C9: =IF(A11="x","DeActivated","~TimeSlices") -> ~TimeSlices | I9: =IF(A11="x","DeActivated","~TFM_DINS-AT") -> ~TFM_DINS-AT | N9: =IF(A11="x","DeActivated","~TFM_DINS-AT") -> ~TFM_DINS-AT | S9: =IF(A11="x","DeActivated","~TFM_DINS-AT") -> ~TFM_DINS-AT | X9: =IF(A11="x","DeActivated","~TFM_INS-AT") -> ~TFM_INS-AT | AC9: =IF(A11="x","DeActivated","~TFM_INS-AT") -> ~TFM_INS-AT | AG9: =IF(A11="x","DeActivated","~TFM_DINS-AT") -> ~TFM_DINS-AT | AK9: =IF(A11="x","DeActivated","~TFM_INS-AT") -> ~TFM_INS-AT
A10: ts_012 | C10: season | D10: weekly | E10: daynite | F10: wparent | G10: dparent | I10: commodity | J10: timeslice | K10: com_fr | L10: process | N10: commodity | O10: timeslice | P10: com_fr | Q10: process | S10: commodity | T10: timeslice | U10: com_fr | V10: process | X10: g_yrfr | Y10: com_fr | Z10: timeslice | AA10: cset_set | AC10: cset_set | AD10: timeslice | AE10: com_fr | AG10: commodity | AH10: timeslice | AI10: com_pkflx | AK10: Year | AL10: timeslice | AM10: ncap_afs | AN10: pset_ci
A11: =IFERROR(IF(Veda!D5=A10,"ok","x"),"") -> ok | C11: S01 | D11: a | E11: H01 | F11: S01,S02,S03,S04 | G11: a | I11: elc_spv_001 | J11: S01aH01 | K11: 0.0042037487 | L11: IMPNRGZ | N11: elc_won_001 | O11: S01aH01 | P11: 0.040922778 | Q11: IMPNRGZ | S11: elc_wof_001 | T11: S01aH01 | U11: 0.053342882 | V11: IMPNRGZ | X11: 0.047146119 | Y11: 0.018618866 | Z11: S01aH01 | AA11: dem_transport | AC11: dem_agriculture,dem_commercial,dem_industry,dem_residential | AD11: S01aH01 | AE11: 0.05126905 | AG11: ELC | AH11: S01aH01 | AI11: 0.054527255 | AK11: 2020 | AL11: S01 | AM11: 0.48784461 | AN11: hydro
C12: S02 | E12: H02 | G12: a | I12: elc_spv_001 | J12: S01aH02 | K12: 0.24139678 | L12: IMPNRGZ | N12: elc_won_001 | O12: S01aH02 | P12: 0.073425397 | Q12: IMPNRGZ | S12: elc_wof_001 | T12: S01aH02 | U12: 0.098239817 | V12: IMPNRGZ | X12: 0.080821918 | Y12: 0.11760005 | Z12: S01aH02 | AA12: dem_transport | AC12: dem_agriculture,dem_commercial,dem_industry,dem_residential | AD12: S01aH02 | AE12: 0.066219522 | AG12: ELC | AH12: S01aH02 | AI12: 0.22109836 | AK12: 2020 | AL12: S02 | AM12: 0.46480916 | AN12: hydro
C13: S03 | E13: H03 | G13: a | I13: elc_spv_001 | J13: S01aH03 | K13: 0.013078311 | L13: IMPNRGZ | N13: elc_won_001 | O13: S01aH03 | P13: 0.030778153 | Q13: IMPNRGZ | S13: elc_wof_001 | T13: S01aH03 | U13: 0.040723397 | V13: IMPNRGZ | X13: 0.033675799 | Y13: 0.025424923 | Z13: S01aH03 | AA13: dem_transport | AC13: dem_agriculture,dem_commercial,dem_industry,dem_residential | AD13: S01aH03 | AE13: 0.035683016 | AG13: ELC | AH13: S01aH03 | AI13: 0.074409023 | AK13: 2020 | AL13: S03 | AM13: 0.50477348 | AN13: hydro
C14: S04 | I14: elc_spv_001 | J14: S02aH01 | K14: 0 | L14: IMPNRGZ | N14: elc_won_001 | O14: S02aH01 | P14: 0.0858366 | Q14: IMPNRGZ | S14: elc_wof_001 | T14: S02aH01 | U14: 0.10466019 | V14: IMPNRGZ | X14: 0.097488584 | Y14: 0.038500029 | Z14: S02aH01 | AA14: dem_transport | AC14: dem_agriculture,dem_commercial,dem_industry,dem_residential | AD14: S02aH01 | AE14: 0.11053902 | AG14: ELC | AH14: S02aH01 | AI14: 0.19212715 | AK14: 2020 | AL14: S04 | AM14: 0.5086855 | AN14: hydro
I15: elc_spv_001 | J15: S02aH02 | K15: 0.22616151 | L15: IMPNRGZ | N15: elc_won_001 | O15: S02aH02 | P15: 0.15028546 | Q15: IMPNRGZ | S15: elc_wof_001 | T15: S02aH02 | U15: 0.18218937 | V15: IMPNRGZ | X15: 0.16712329 | Y15: 0.24317298 | Z15: S02aH02 | AA15: dem_transport | AC15: dem_agriculture,dem_commercial,dem_industry,dem_residential | AD15: S02aH02 | AE15: 0.14560008 | AG15: ELC | AH15: S02aH02 | AI15: 0.40616617 | AK15: 2021 | AL15: S01 | AM15: 0.44433726 | AN15: hydro
I16: elc_spv_001 | J16: S02aH03 | K16: 0.0013351281 | L16: IMPNRGZ | N16: elc_won_001 | O16: S02aH03 | P16: 0.061458504 | Q16: IMPNRGZ | S16: elc_wof_001 | T16: S02aH03 | U16: 0.073206055 | V16: IMPNRGZ | X16: 0.069634703 | Y16: 0.052573569 | Z16: S02aH03 | AA16: dem_transport | AC16: dem_agriculture,dem_commercial,dem_industry,dem_residential | AD16: S02aH03 | AE16: 0.076736713 | AG16: ELC | AH16: S02aH03 | AI16: 0.24372057 | AK16: 2021 | AL16: S02 | AM16: 0.43701326 | AN16: hydro
I17: elc_spv_001 | J17: S03aH01 | K17: 0.0020006381 | L17: IMPNRGZ | N17: elc_won_001 | O17: S03aH01 | P17: 0.11288554 | Q17: IMPNRGZ | S17: elc_wof_001 | T17: S03aH01 | U17: 0.096729598 | V17: IMPNRGZ | X17: 0.098287671 | Y17: 0.038815603 | Z17: S03aH01 | AA17: dem_transport | AC17: dem_agriculture,dem_commercial,dem_industry,dem_residential | AD17: S03aH01 | AE17: 0.11766171 | AG17: ELC | AH17: S03aH01 | AI17: 0.17707708 | AK17: 2021 | AL17: S03 | AM17: 0.54368774 | AN17: hydro
I18: elc_spv_001 | J18: S03aH02 | K18: 0.26960406 | L18: IMPNRGZ | N18: elc_won_001 | O18: S03aH02 | P18: 0.20217891 | Q18: IMPNRGZ | S18: elc_wof_001 | T18: S03aH02 | U18: 0.16993672 | V18: IMPNRGZ | X18: 0.16849315 | Y18: 0.2451662 | Z18: S03aH02 | AA18: dem_transport | AC18: dem_agriculture,dem_commercial,dem_industry,dem_residential | AD18: S03aH02 | AE18: 0.1561753 | AG18: ELC | AH18: S03aH02 | AI18: 0.39073889 | AK18: 2021 | AL18: S04 | AM18: 0.52120395 | AN18: hydro
I19: elc_spv_001 | J19: S03aH03 | K19: 0.00089412696 | L19: IMPNRGZ | N19: elc_won_001 | O19: S03aH03 | P19: 0.083316222 | Q19: IMPNRGZ | S19: elc_wof_001 | T19: S03aH03 | U19: 0.067504192 | V19: IMPNRGZ | X19: 0.070205479 | Y19: 0.0530045 | Z19: S03aH03 | AA19: dem_transport | AC19: dem_agriculture,dem_commercial,dem_industry,dem_residential | AD19: S03aH03 | AE19: 0.082539771 | AG19: ELC | AH19: S03aH03 | AI19: 0.23926714 | AK19: 2022 | AL19: S01 | AM19: 0.44973301 | AN19: hydro
I20: elc_spv_001 | J20: S04aH01 | K20: 0.0074078848 | L20: IMPNRGZ | N20: elc_won_001 | O20: S04aH01 | P20: 0.042008124 | Q20: IMPNRGZ | S20: elc_wof_001 | T20: S04aH01 | U20: 0.033364681 | V20: IMPNRGZ | X20: 0.048744292 | Y20: 0.019250015 | Z20: S04aH01 | AA20: dem_transport | AC20: dem_agriculture,dem_commercial,dem_industry,dem_residential | AD20: S04aH01 | AE20: 0.052561571 | AG20: ELC | AH20: S04aH01 | AI20: 0.078199338 | AK20: 2022 | AL20: S02 | AM20: 0.44696382 | AN20: hydro
I21: elc_spv_001 | J21: S04aH02 | K21: 0.22504026 | L21: IMPNRGZ | N21: elc_won_001 | O21: S04aH02 | P21: 0.083817938 | Q21: IMPNRGZ | S21: elc_wof_001 | T21: S04aH02 | U21: 0.056240402 | V21: IMPNRGZ | X21: 0.083561644 | Y21: 0.12158649 | Z21: S04aH02 | AA21: dem_transport | AC21: dem_agriculture,dem_commercial,dem_industry,dem_residential | AD21: S04aH02 | AE21: 0.068361801 | AG21: ELC | AH21: S04aH02 | AI21: 0.25207431 | AK21: 2022 | AL21: S03 | AM21: 0.56796311 | AN21: hydro
I22: elc_spv_001 | J22: S04aH03 | K22: 0.008877554 | L22: IMPNRGZ | N22: elc_won_001 | O22: S04aH03 | P22: 0.033086373 | Q22: IMPNRGZ | S22: elc_wof_001 | T22: S04aH03 | U22: 0.023862695 | V22: IMPNRGZ | X22: 0.034817352 | Y22: 0.026286785 | Z22: S04aH03 | AA22: dem_transport | AC22: dem_agriculture,dem_commercial,dem_industry,dem_residential | AD22: S04aH03 | AE22: 0.036652444 | AG22: ELC | AH22: S04aH03 | AI22: 0.1018818 | AK22: 2022 | AL22: S04 | AM22: 0.55699903 | AN22: hydro
I23: elc_spv_002 | J23: S01aH01 | K23: 0.011308122 | L23: IMPNRGZ | N23: elc_won_002 | O23: S01aH01 | P23: 0.037134461 | Q23: IMPNRGZ | S23: elc_wof_002 | T23: S01aH01 | U23: 0.052206153 | V23: IMPNRGZ | AC23: dem_agriculture,dem_commercial,dem_industry,dem_residential | AD23: S01aH01 | AE23: 0.047550272 | AK23: 2025 | AL23: S01 | AM23: 0.49025 | AN23: hydro
I24: elc_spv_002 | J24: S01aH02 | K24: 0.22375061 | L24: IMPNRGZ | N24: elc_won_002 | O24: S01aH02 | P24: 0.071483002 | Q24: IMPNRGZ | S24: elc_wof_002 | T24: S01aH02 | U24: 0.090359016 | V24: IMPNRGZ | AC24: dem_agriculture,dem_commercial,dem_industry,dem_residential | AD24: S01aH02 | AE24: 0.080136732 | AK24: 2025 | AL24: S02 | AM24: 0.5001 | AN24: hydro
I25: elc_spv_002 | J25: S01aH03 | K25: 0.0029512368 | L25: IMPNRGZ | N25: elc_won_002 | O25: S01aH03 | P25: 0.02868098 | Q25: IMPNRGZ | S25: elc_wof_002 | T25: S01aH03 | U25: 0.037253481 | V25: IMPNRGZ | AC25: dem_agriculture,dem_commercial,dem_industry,dem_residential | AD25: S01aH03 | AE25: 0.033904849 | AK25: 2025 | AL25: S03 | AM25: 0.524975 | AN25: hydro
I26: elc_spv_002 | J26: S02aH01 | K26: 0.00194742 | L26: IMPNRGZ | N26: elc_won_002 | O26: S02aH01 | P26: 0.081662307 | Q26: IMPNRGZ | S26: elc_wof_002 | T26: S02aH01 | U26: 0.094885371 | V26: IMPNRGZ | AC26: dem_agriculture,dem_commercial,dem_industry,dem_residential | AD26: S02aH01 | AE26: 0.098341437 | AK26: 2025 | AL26: S04 | AM26: 0.50445 | AN26: hydro
I27: elc_spv_002 | J27: S02aH02 | K27: 0.2343161 | L27: IMPNRGZ | N27: elc_won_002 | O27: S02aH02 | P27: 0.14810559 | Q27: IMPNRGZ | S27: elc_wof_002 | T27: S02aH02 | U27: 0.16199641 | V27: IMPNRGZ | AC27: dem_agriculture,dem_commercial,dem_industry,dem_residential | AD27: S02aH02 | AE27: 0.165794 | AK27: 2026 | AL27: S01 | AM27: 0.4814 | AN27: hydro
I28: elc_spv_002 | J28: S02aH03 | K28: 0 | L28: IMPNRGZ | N28: elc_won_002 | O28: S02aH03 | P28: 0.058215563 | Q28: IMPNRGZ | S28: elc_wof_002 | T28: S02aH03 | U28: 0.068333221 | V28: IMPNRGZ | AC28: dem_agriculture,dem_commercial,dem_industry,dem_residential | AD28: S02aH03 | AE28: 0.07010273 | AK28: 2026 | AL28: S02 | AM28: 0.463825 | AN28: hydro
I29: elc_spv_002 | J29: S03aH01 | K29: 0.0073032457 | L29: IMPNRGZ | N29: elc_won_002 | O29: S03aH01 | P29: 0.11966953 | Q29: IMPNRGZ | S29: elc_wof_002 | T29: S03aH01 | U29: 0.10906384 | V29: IMPNRGZ | AC29: dem_agriculture,dem_commercial,dem_industry,dem_residential | AD29: S03aH01 | AE29: 0.099194735 | AK29: 2026 | AL29: S03 | AM29: 0.54475 | AN29: hydro
I30: elc_spv_002 | J30: S03aH02 | K30: 0.26904568 | L30: IMPNRGZ | N30: elc_won_002 | O30: S03aH02 | P30: 0.21907676 | Q30: IMPNRGZ | S30: elc_wof_002 | T30: S03aH02 | U30: 0.18767514 | V30: IMPNRGZ | AC30: dem_agriculture,dem_commercial,dem_industry,dem_residential | AD30: S03aH02 | AE30: 0.16715282 | AK30: 2026 | AL30: S04 | AM30: 0.53075 | AN30: hydro
I31: elc_spv_002 | J31: S03aH03 | K31: 0 | L31: IMPNRGZ | N31: elc_won_002 | O31: S03aH03 | P31: 0.089563654 | Q31: IMPNRGZ | S31: elc_wof_002 | T31: S03aH03 | U31: 0.080075767 | V31: IMPNRGZ | AC31: dem_agriculture,dem_commercial,dem_industry,dem_residential | AD31: S03aH03 | AE31: 0.070757722 | AK31: 2027 | AL31: S01 | AM31: 0.484 | AN31: hydro
I32: elc_spv_002 | J32: S04aH01 | K32: 0.020455698 | L32: IMPNRGZ | N32: elc_won_002 | O32: S04aH01 | P32: 0.038940275 | Q32: IMPNRGZ | S32: elc_wof_002 | T32: S04aH01 | U32: 0.035353436 | V32: IMPNRGZ | AC32: dem_agriculture,dem_commercial,dem_industry,dem_residential | AD32: S04aH01 | AE32: 0.049147027 | AK32: 2027 | AL32: S02 | AM32: 0.461075 | AN32: hydro
I33: elc_spv_002 | J33: S04aH02 | K33: 0.22783998 | L33: IMPNRGZ | N33: elc_won_002 | O33: S04aH02 | P33: 0.077871236 | Q33: IMPNRGZ | S33: elc_wof_002 | T33: S04aH02 | U33: 0.057648939 | V33: IMPNRGZ | AC33: dem_agriculture,dem_commercial,dem_industry,dem_residential | AD33: S04aH02 | AE33: 0.082869354 | AK33: 2027 | AL33: S03 | AM33: 0.535925 | AN33: hydro
I34: elc_spv_002 | J34: S04aH03 | K34: 0.0010819071 | L34: IMPNRGZ | N34: elc_won_002 | O34: S04aH03 | P34: 0.029596649 | Q34: IMPNRGZ | S34: elc_wof_002 | T34: S04aH03 | U34: 0.025149235 | V34: IMPNRGZ | AC34: dem_agriculture,dem_commercial,dem_industry,dem_residential | AD34: S04aH03 | AE34: 0.035048326 | AK34: 2027 | AL34: S04 | AM34: 0.5205 | AN34: hydro
